<?xml version="1.0" encoding="utf-8"?>
<robot xmlns:xacro="http://www.ros.org/wiki/xacro">
  <xacro:macro name="mason">
    <link name="world" />
    
    <link name="right_bar"> </link>
    <link name="left_bar"> </link>
    <link name="horizontal_bar"> </link>

    <joint name="motor_left" type="continuous">
      <parent link="world"/>
      <child link="left_bar"/>
      <axis xyz="0 0 1"/>
    </joint>

    <joint name="motor_right" type="continuous">
      <parent link="world"/>
      <child link="right_bar"/>
      <axis xyz="0 0 1"/>
    </joint>

    <joint name="motor_horizontal" type="continuous">
      <parent link="world"/>
      <child link="horizontal_bar"/>
      <axis xyz="0 0 1"/>
    </joint>

  </xacro:macro>

</robot>