<?xml version="1.0" encoding="utf-8"?>
<robot xmlns:xacro="http://www.ros.org/wiki/xacro">
  <xacro:macro name="mason">
    <link name="world" />
    <link
      name="RightBar">
      <inertial>
        <origin
          xyz="-1.34046800536292 -0.272459904837881 0.0490096577850858"
          rpy="0 0 0" />
        <mass
          value="5.55312910017424" />
        <inertia
          ixx="0.782838152186612"
          ixy="1.21611266476934E-17"
          ixz="-4.49093050475392E-19"
          iyy="0.782838152186612"
          iyz="-4.74065607624699E-17"
          izz="0.00154494115749392" />
      </inertial>
      <visual>
        <origin
          xyz="0 0 0"
          rpy="0 0 0" />
        <geometry>
          <mesh
            filename="$(find mason_description)/description/meshes/RightBar.STL" />
        </geometry>
        <material
          name="">
          <color
            rgba="0.647058823529412 0.619607843137255 0.588235294117647 1" />
        </material>
      </visual>
      <collision>
        <origin
          xyz="0 0 0"
          rpy="0 0 0" />
        <geometry>
          <mesh
            filename="$(find mason_description)/description/meshes/RightBar.STL" />
        </geometry>
      </collision>
    </link>

    <joint name="world_to_rightBar" type="fixed">
      <origin rpy="0 0 0" xyz="0 0 0" />
      <parent link="world" />
      <child link="RightBar" />
    </joint>

    <link
      name="RightBracketTop">
      <inertial>
        <origin
          xyz="-0.0307068750932176 0.0431985153087461 -6.29781428340692E-07"
          rpy="0 0 0" />
        <mass
          value="0.000214749814862541" />
        <inertia
          ixx="5.04014900228215E-07"
          ixy="1.41838418654998E-07"
          ixz="-1.26884314163884E-12"
          iyy="2.49863376560336E-07"
          iyz="4.06202656032707E-12"
          izz="5.24669847054164E-07" />
      </inertial>
      <visual>
        <origin
          xyz="0 0 0"
          rpy="0 0 0" />
        <geometry>
          <mesh
            filename="$(find mason_description)/description/meshes/RightBracketTop.STL" />
        </geometry>
        <material
          name="">
          <color
            rgba="0.4 0.4 0.4 1" />
        </material>
      </visual>
      <collision>
        <origin
          xyz="0 0 0"
          rpy="0 0 0" />
        <geometry>
          <mesh
            filename="$(find mason_description)/description/meshes/RightBracketTop.STL" />
        </geometry>
      </collision>
    </link>
    <joint
      name="RBT_RB"
      type="fixed">
      <origin
        xyz="-1.43796800536526 -0.392459904838281 0.589966540848759"
        rpy="-3.14159265358979 0 3.14159265358979" />
      <parent
        link="RightBar" />
      <child
        link="RightBracketTop" />
      <axis
        xyz="0 0 0" />
    </joint>
    <link
      name="RightBracketBottom">
      <inertial>
        <origin
          xyz="-0.0307095280172158 0.0432034395198194 4.9852419820029E-07"
          rpy="0 0 0" />
        <mass
          value="0.214769503083403" />
        <inertia
          ixx="0.000504017787094408"
          ixy="0.000141840084805534"
          ixz="-2.55519874076561E-09"
          iyy="0.000249864733012362"
          iyz="5.55018450253158E-09"
          izz="0.000524673250439356" />
      </inertial>
      <visual>
        <origin
          xyz="0 0 0"
          rpy="0 0 0" />
        <geometry>
          <mesh
            filename="$(find mason_description)/description/meshes/RightBracketBottom.STL" />
        </geometry>
        <material
          name="">
          <color
            rgba="0.792156862745098 0.819607843137255 0.933333333333333 1" />
        </material>
      </visual>
      <collision>
        <origin
          xyz="0 0 0"
          rpy="0 0 0" />
        <geometry>
          <mesh
            filename="$(find mason_description)/description/meshes/RightBracketBottom.STL" />
        </geometry>
      </collision>
    </link>
    <joint
      name="RBB_RB"
      type="fixed">
      <origin
        xyz="-1.43796800536388 -0.392459904837929 -0.437021328543411"
        rpy="-3.14159265358979 0 3.14159265358979" />
      <parent
        link="RightBar" />
      <child
        link="RightBracketBottom" />
      <axis
        xyz="0 0 0" />
    </joint>
    <link
      name="LeftBar">
      <inertial>
        <origin
          xyz="6.93889390390723E-17 0.65 5.55111512312578E-17"
          rpy="0 0 0" />
        <mass
          value="5.55312910017434" />
        <inertia
          ixx="0.782838152186632"
          ixy="-3.84480360700148E-18"
          ixz="-1.03516199438847E-17"
          iyy="0.00154494115749394"
          iyz="-1.94626228426363E-18"
          izz="0.782838152186632" />
      </inertial>
      <visual>
        <origin
          xyz="0 0 0"
          rpy="0 0 0" />
        <geometry>
          <mesh
            filename="$(find mason_description)/description/meshes/LeftBar.STL" />
        </geometry>
        <material
          name="">
          <color
            rgba="0.647058823529412 0.619607843137255 0.588235294117647 1" />
        </material>
      </visual>
      <collision>
        <origin
          xyz="0 0 0"
          rpy="0 0 0" />
        <geometry>
          <mesh
            filename="$(find mason_description)/description/meshes/LeftBar.STL" />
        </geometry>
      </collision>
    </link>
    <joint
      name="LB_RB"
      type="fixed">
      <origin
        xyz="-0.0824680053628981 -0.272459904837888 -0.600990342214936"
        rpy="1.5707963267949 0 0" />
      <parent
        link="RightBar" />
      <child
        link="LeftBar" />
      <axis
        xyz="0 0 0" />
    </joint>
    <link
      name="LeftBracketTop">
      <inertial>
        <origin
          xyz="-0.0307068750922646 0.0431985153087082 -6.29781428118648E-07"
          rpy="0 0 0" />
        <mass
          value="0.000214749814862542" />
        <inertia
          ixx="5.04014900228219E-07"
          ixy="1.41838418654999E-07"
          ixz="-1.26884314002485E-12"
          iyy="2.49863376560337E-07"
          iyz="4.06202656005297E-12"
          izz="5.24669847054167E-07" />
      </inertial>
      <visual>
        <origin
          xyz="0 0 0"
          rpy="0 0 0" />
        <geometry>
          <mesh
            filename="$(find mason_description)/description/meshes/LeftBracketTop.STL" />
        </geometry>
        <material
          name="">
          <color
            rgba="0.4 0.4 0.4 1" />
        </material>
      </visual>
      <collision>
        <origin
          xyz="0 0 0"
          rpy="0 0 0" />
        <geometry>
          <mesh
            filename="$(find mason_description)/description/meshes/LeftBracketTop.STL" />
        </geometry>
      </collision>
    </link>
    <joint
      name="LBT_LB"
      type="fixed">
      <origin
        xyz="0.0975000000014027 1.1909568830637 0.120000000000417"
        rpy="-1.5707963267949 0 0" />
      <parent
        link="LeftBar" />
      <child
        link="LeftBracketTop" />
      <axis
        xyz="0 0 0" />
    </joint>
    <link
      name="LeftBracketBottom">
      <inertial>
        <origin
          xyz="-0.0307068750986306 0.0431985153105867 -6.2978142628678E-07"
          rpy="0 0 0" />
        <mass
          value="0.000214749814862542" />
        <inertia
          ixx="5.04014900228218E-07"
          ixy="1.41838418654998E-07"
          ixz="-1.26884313983503E-12"
          iyy="2.49863376560336E-07"
          iyz="4.06202655988751E-12"
          izz="5.24669847054166E-07" />
      </inertial>
      <visual>
        <origin
          xyz="0 0 0"
          rpy="0 0 0" />
        <geometry>
          <mesh
            filename="$(find mason_description)/description/meshes/LeftBracketBottom.STL" />
        </geometry>
        <material
          name="">
          <color
            rgba="0.4 0.4 0.4 1" />
        </material>
      </visual>
      <collision>
        <origin
          xyz="0 0 0"
          rpy="0 0 0" />
        <geometry>
          <mesh
            filename="$(find mason_description)/description/meshes/LeftBracketBottom.STL" />
        </geometry>
      </collision>
    </link>
    <joint
      name="LBB_LB"
      type="fixed">
      <origin
        xyz="0.0974999999999891 0.163969013671525 0.12"
        rpy="-1.5707963267949 0 0" />
      <parent
        link="LeftBar" />
      <child
        link="LeftBracketBottom" />
      <axis
        xyz="0 0 0" />
    </joint>
    <link
      name="WheelHinge1Right">
      <inertial>
        <origin
          xyz="-0.0150182712144393 -0.176153022927531 0.0345338768293388"
          rpy="0 0 0" />
        <mass
          value="0.214742930836365" />
        <inertia
          ixx="0.000830775779814993"
          ixy="-3.28525561723032E-05"
          ixz="-0.000115730835677916"
          iyy="0.000823146607327791"
          iyz="-0.000146137364884107"
          izz="0.000149954007145533" />
      </inertial>
      <visual>
        <origin
          xyz="0 0 0"
          rpy="0 0 0" />
        <geometry>
          <mesh
            filename="$(find mason_description)/description/meshes/WheelHinge1Right.STL" />
        </geometry>
        <material
          name="">
          <color
            rgba="0.792156862745098 0.819607843137255 0.933333333333333 1" />
        </material>
      </visual>
      <collision>
        <origin
          xyz="0 0 0"
          rpy="0 0 0" />
        <geometry>
          <mesh
            filename="$(find mason_description)/description/meshes/WheelHinge1Right.STL" />
        </geometry>
      </collision>
    </link>
    <joint
      name="gantryVertical"
      type="prismatic">
      <origin
        xyz="-1.34046800536291 -0.272459904837837 0.0227356955196975"
        rpy="1.5707963267949 0 3.14159265358979" />
      <parent
        link="RightBar" />
      <child
        link="WheelHinge1Right" />
      <axis
        xyz="0 1 0" />
      <limit
        lower="-0.4"
        upper="0.4"
        effort="100000"
        velocity="10" />
    </joint>
    <link
      name="Horizontal Bar Bottom">
      <inertial>
        <origin
          xyz="-1.45439216225896E-14 -0.649999999999998 0.175692112504627"
          rpy="0 0 0" />
        <mass
          value="5.55312910017434" />
        <inertia
          ixx="0.782838152186632"
          ixy="-2.04774376725019E-14"
          ixz="1.10469557216151E-17"
          iyy="0.00154494115749394"
          iyz="2.25117904803473E-17"
          izz="0.782838152186632" />
      </inertial>
      <visual>
        <origin
          xyz="0 0 0"
          rpy="0 0 0" />
        <geometry>
          <mesh
            filename="$(find mason_description)/description/meshes/Horizontal Bar Bottom.STL" />
        </geometry>
        <material
          name="">
          <color
            rgba="0.647058823529412 0.619607843137255 0.588235294117647 1" />
        </material>
      </visual>
      <collision>
        <origin
          xyz="0 0 0"
          rpy="0 0 0" />
        <geometry>
          <mesh
            filename="$(find mason_description)/description/meshes/Horizontal Bar Bottom.STL" />
        </geometry>
      </collision>
    </link>
    <joint
      name="HBB_WH1R"
      type="fixed">
      <origin
        xyz="0.0209999999999979 0.0380000000000099 0.0409999999999176"
        rpy="1.5707963267949 1.5707963267949 0" />
      <parent
        link="WheelHinge1Right" />
      <child
        link="Horizontal Bar Bottom" />
      <axis
        xyz="0 0 0" />
    </joint>
    <link
      name="Horizontal Bar Connector">
      <inertial>
        <origin
          xyz="-1.89015469942433E-14 -0.275692112504631 -0.00999999999998824"
          rpy="0 0 0" />
        <mass
          value="0.0683596037592093" />
        <inertia
          ixx="0.000174202119847688"
          ixy="3.04927208120603E-18"
          ixz="2.43813450228267E-19"
          iyy="1.45830371947947E-05"
          iyz="6.13992141572174E-20"
          izz="0.000184227850125202" />
      </inertial>
      <visual>
        <origin
          xyz="0 0 0"
          rpy="0 0 0" />
        <geometry>
          <mesh
            filename="$(find mason_description)/description/meshes/Horizontal Bar Connector.STL" />
        </geometry>
        <material
          name="">
          <color
            rgba="0.792156862745098 0.819607843137255 0.933333333333333 1" />
        </material>
      </visual>
      <collision>
        <origin
          xyz="0 0 0"
          rpy="0 0 0" />
        <geometry>
          <mesh
            filename="$(find mason_description)/description/meshes/Horizontal Bar Connector.STL" />
        </geometry>
      </collision>
    </link>
    <joint
      name="HBC_HBB"
      type="fixed">
      <origin
        xyz="0 0 -0.200000000000012"
        rpy="-1.5707963267949 0 0" />
      <parent
        link="Horizontal Bar Bottom" />
      <child
        link="Horizontal Bar Connector" />
      <axis
        xyz="0 0 0" />
    </joint>
    <link
      name="Horizontal Bar Top">
      <inertial>
        <origin
          xyz="-5.60662627435704E-14 -0.650000000000038 0.175692112504677"
          rpy="0 0 0" />
        <mass
          value="5.55312910017434" />
        <inertia
          ixx="0.782838152186632"
          ixy="-2.04795017439615E-14"
          ixz="1.09824252940783E-17"
          iyy="0.00154494115749394"
          iyz="2.24984591411134E-17"
          izz="0.782838152186632" />
      </inertial>
      <visual>
        <origin
          xyz="0 0 0"
          rpy="0 0 0" />
        <geometry>
          <mesh
            filename="$(find mason_description)/description/meshes/Horizontal Bar Top.STL" />
        </geometry>
        <material
          name="">
          <color
            rgba="0.647058823529412 0.619607843137255 0.588235294117647 1" />
        </material>
      </visual>
      <collision>
        <origin
          xyz="0 0 0"
          rpy="0 0 0" />
        <geometry>
          <mesh
            filename="$(find mason_description)/description/meshes/Horizontal Bar Top.STL" />
        </geometry>
      </collision>
    </link>
    <joint
      name="HBT_HBC"
      type="fixed">
      <origin
        xyz="0 0 0"
        rpy="1.5707963267949 0 0" />
      <parent
        link="Horizontal Bar Connector" />
      <child
        link="Horizontal Bar Top" />
      <axis
        xyz="0 0 0" />
    </joint>
    <link
      name="WheelHinge3Right">
      <inertial>
        <origin
          xyz="-0.024475115492913 -0.200541156171297 0.018727101068815"
          rpy="0 0 0" />
        <mass
          value="0.165316423881629" />
        <inertia
          ixx="0.000304272925724323"
          ixy="3.25327980907543E-05"
          ixz="-2.40251206515419E-05"
          iyy="0.000222306193247368"
          iyz="6.85580657075716E-05"
          izz="0.000154900041141416" />
      </inertial>
      <visual>
        <origin
          xyz="0 0 0"
          rpy="0 0 0" />
        <geometry>
          <mesh
            filename="$(find mason_description)/description/meshes/WheelHinge3Right.STL" />
        </geometry>
        <material
          name="">
          <color
            rgba="0.792156862745098 0.819607843137255 0.933333333333333 1" />
        </material>
      </visual>
      <collision>
        <origin
          xyz="0 0 0"
          rpy="0 0 0" />
        <geometry>
          <mesh
            filename="$(find mason_description)/description/meshes/WheelHinge3Right.STL" />
        </geometry>
      </collision>
    </link>
    <joint
      name="WH3R_HBT"
      type="fixed">
      <origin
        xyz="0.0409999999999521 -0.0209999999999979 -0.0849999999998929"
        rpy="-1.5707963267949 0 1.5707963267949" />
      <parent
        link="Horizontal Bar Top" />
      <child
        link="WheelHinge3Right" />
      <axis
        xyz="0 0 0" />
    </joint>
    <link
      name="Wheel4">
      <inertial>
        <origin
          xyz="8.21565038222616E-15 0.102346514638583 0.142803744130718"
          rpy="0 0 0" />
        <mass
          value="0.211779473167468" />
        <inertia
          ixx="0.000195048438274556"
          ixy="1.61453593881096E-18"
          ixz="-1.12137118131545E-18"
          iyy="0.000122863056698053"
          iyz="3.3881317890172E-21"
          izz="0.000122863056698054" />
      </inertial>
      <visual>
        <origin
          xyz="0 0 0"
          rpy="0 0 0" />
        <geometry>
          <mesh
            filename="$(find mason_description)/description/meshes/Wheel4.STL" />
        </geometry>
        <material
          name="">
          <color
            rgba="0.792156862745098 0.819607843137255 0.933333333333333 1" />
        </material>
      </visual>
      <collision>
        <origin
          xyz="0 0 0"
          rpy="0 0 0" />
        <geometry>
          <mesh
            filename="$(find mason_description)/description/meshes/Wheel4.STL" />
        </geometry>
      </collision>
    </link>
    <joint
      name="wheel4"
      type="fixed">
      <origin
        xyz="0 0.009 0.06"
        rpy="-0.94895 0 3.1416" />
      <parent
        link="WheelHinge3Right" />
      <child
        link="Wheel4" />
      <axis
        xyz="1 0 0" />
    </joint>
    <link
      name="Wheel5">
      <inertial>
        <origin
          xyz="2.17603712826531E-14 -0.167169797186281 0.054055317084847"
          rpy="0 0 0" />
        <mass
          value="0.211779473167468" />
        <inertia
          ixx="0.000195048438274556"
          ixy="6.15932602860008E-19"
          ixz="1.80099673518559E-18"
          iyy="0.000122863056698053"
          iyz="-1.01643953670516E-20"
          izz="0.000122863056698053" />
      </inertial>
      <visual>
        <origin
          xyz="0 0 0"
          rpy="0 0 0" />
        <geometry>
          <mesh
            filename="$(find mason_description)/description/meshes/Wheel5.STL" />
        </geometry>
        <material
          name="">
          <color
            rgba="0.792156862745098 0.819607843137255 0.933333333333333 1" />
        </material>
      </visual>
      <collision>
        <origin
          xyz="0 0 0"
          rpy="0 0 0" />
        <geometry>
          <mesh
            filename="$(find mason_description)/description/meshes/Wheel5.STL" />
        </geometry>
      </collision>
    </link>
    <joint
      name="wheel5"
      type="fixed">
      <origin
        xyz="0 0.009 -0.06"
        rpy="0.31274 0 0" />
      <parent
        link="WheelHinge3Right" />
      <child
        link="Wheel5" />
      <axis
        xyz="1 0 0" />
    </joint>
    <link
      name="WheelBracketTop">
      <inertial>
        <origin
          xyz="-0.872381906901376 0.126360863917517 0.0316973524931644"
          rpy="0 0 0" />
        <mass
          value="0.240740698245303" />
        <inertia
          ixx="0.000663222771568812"
          ixy="-8.08191067052129E-07"
          ixz="-1.07609063234249E-08"
          iyy="0.000252811429413381"
          iyz="2.37785454057574E-07"
          izz="0.000647287300412067" />
      </inertial>
      <visual>
        <origin
          xyz="0 0 0"
          rpy="0 0 0" />
        <geometry>
          <mesh
            filename="$(find mason_description)/description/meshes/WheelBracketTop.STL" />
        </geometry>
        <material
          name="">
          <color
            rgba="0.792156862745098 0.819607843137255 0.933333333333333 1" />
        </material>
      </visual>
      <collision>
        <origin
          xyz="0 0 0"
          rpy="0 0 0" />
        <geometry>
          <mesh
            filename="$(find mason_description)/description/meshes/WheelBracketTop.STL" />
        </geometry>
      </collision>
    </link>
    <joint
      name="gantryHorizontal"
      type="prismatic">
      <origin
        xyz="-0.031000000000083 -1.44312518930694 0.236800874091782"
        rpy="-1.5707963267949 0 -1.5707963267949" />
      <parent
        link="Horizontal Bar Top" />
      <child
        link="WheelBracketTop" />
      <axis
        xyz="1 0 0" />
      <limit
        lower="-0.4"
        upper="0.4"
        effort="100000"
        velocity="10" />
    </joint>
    <link
      name="GearboxTop">
      <inertial>
        <origin
          xyz="-0.0930765679945016 -0.175684521373279 0.0293276986135527"
          rpy="0 0 0" />
        <mass
          value="0.000256548604677884" />
        <inertia
          ixx="2.54736828036315E-07"
          ixy="-6.40383187167403E-10"
          ixz="1.59283956942334E-16"
          iyy="2.56149067709212E-07"
          iyz="-1.21081864779379E-10"
          izz="1.26043942396443E-07" />
      </inertial>
      <visual>
        <origin
          xyz="0 0 0"
          rpy="0 0 0" />
        <geometry>
          <mesh
            filename="$(find mason_description)/description/meshes/GearboxTop.STL" />
        </geometry>
        <material
          name="">
          <color
            rgba="0.8 0.8 0.8 1" />
        </material>
      </visual>
      <collision>
        <origin
          xyz="0 0 0"
          rpy="0 0 0" />
        <geometry>
          <mesh
            filename="$(find mason_description)/description/meshes/GearboxTop.STL" />
        </geometry>
      </collision>
    </link>
    <joint
      name="GBT_WBT"
      type="fixed">
      <origin
        xyz="-0.779241240549766 0.296800874091835 -0.0714999999999975"
        rpy="0 0 0" />
      <parent
        link="WheelBracketTop" />
      <child
        link="GearboxTop" />
      <axis
        xyz="0 0 0" />
    </joint>
    <link
      name="Monteerplaatje Top">
      <inertial>
        <origin
          xyz="-0.0930765679819273 -0.176169493203825 -0.0165014483312182"
          rpy="0 0 0" />
        <mass
          value="0.0317648196657452" />
        <inertia
          ixx="2.34438829670901E-05"
          ixy="-2.32832247950655E-13"
          ixz="9.64168733910027E-16"
          iyy="4.404984317719E-05"
          iyz="6.22286402330486E-07"
          izz="3.24550740416562E-05" />
      </inertial>
      <visual>
        <origin
          xyz="0 0 0"
          rpy="0 0 0" />
        <geometry>
          <mesh
            filename="$(find mason_description)/description/meshes/Monteerplaatje Top.STL" />
        </geometry>
        <material
          name="">
          <color
            rgba="0.792156862745098 0.819607843137255 0.933333333333333 1" />
        </material>
      </visual>
      <collision>
        <origin
          xyz="0 0 0"
          rpy="0 0 0" />
        <geometry>
          <mesh
            filename="$(find mason_description)/description/meshes/Monteerplaatje Top.STL" />
        </geometry>
      </collision>
    </link>
    <joint
      name="MOPT_GBT"
      type="fixed">
      <origin
        xyz="0 0 -0.0230000000000023"
        rpy="0 0 0" />
      <parent
        link="GearboxTop" />
      <child
        link="Monteerplaatje Top" />
      <axis
        xyz="0 0 0" />
    </joint>
    <link
      name="Motor Top">
      <inertial>
        <origin
          xyz="-0.12458134220637 0.154963293939379 -0.020759323654756"
          rpy="0 0 0" />
        <mass
          value="0.136603032784616" />
        <inertia
          ixx="5.81168092126515E-05"
          ixy="-1.76551144614545E-09"
          ixz="2.34069909389152E-08"
          iyy="5.81183003770313E-05"
          iyz="-3.52934759718909E-08"
          izz="6.65314608747261E-05" />
      </inertial>
      <visual>
        <origin
          xyz="0 0 0"
          rpy="0 0 0" />
        <geometry>
          <mesh
            filename="$(find mason_description)/description/meshes/Motor Top.STL" />
        </geometry>
        <material
          name="">
          <color
            rgba="0.792156862745098 0.819607843137255 0.933333333333333 1" />
        </material>
      </visual>
      <collision>
        <origin
          xyz="0 0 0"
          rpy="0 0 0" />
        <geometry>
          <mesh
            filename="$(find mason_description)/description/meshes/Motor Top.STL" />
        </geometry>
      </collision>
    </link>
    <joint
      name="MotorTop"
      type="fixed">
      <origin
        xyz="0 0 -0.0110000000000023"
        rpy="0 0 1.97726991233421" />
      <parent
        link="Monteerplaatje Top" />
      <child
        link="Motor Top" />
      <axis
        xyz="0 0 -1" />
    </joint>
    <link
      name="ToolHeads">
      <inertial>
        <origin
          xyz="-0.113150727121495 -0.250631814640357 0.0827280543801633"
          rpy="0 0 0" />
        <mass
          value="1.7336854049465" />
        <inertia
          ixx="0.00430179804020702"
          ixy="-4.8597027058172E-07"
          ixz="-1.06284885018653E-05"
          iyy="0.00596010692651662"
          iyz="0.000658922910592316"
          izz="0.00672061175674211" />
      </inertial>
      <visual>
        <origin
          xyz="0 0 0"
          rpy="0 0 0" />
        <geometry>
          <mesh
            filename="$(find mason_description)/description/meshes/ToolHeads.STL" />
        </geometry>
        <material
          name="">
          <color
            rgba="0.792156862745098 0.819607843137255 0.933333333333333 1" />
        </material>
      </visual>
      <collision>
        <origin
          xyz="0 0 0"
          rpy="0 0 0" />
        <geometry>
          <mesh
            filename="$(find mason_description)/description/meshes/ToolHeads.STL" />
        </geometry>
      </collision>
    </link>
    <joint
      name="TH_WBT"
      type="fixed">
      <origin
        xyz="-0.779241240550579 0.136800874091995 -0.0100000000000198"
        rpy="0 0 0" />
      <parent
        link="WheelBracketTop" />
      <child
        link="ToolHeads" />
      <axis
        xyz="0 0 0" />
    </joint>
    <link
      name="Wheel12">
      <inertial>
        <origin
          xyz="-0.0997666770939831 -0.171981324697836 -1.55431223447522E-15"
          rpy="0 0 0" />
        <mass
          value="0.0529405486019684" />
        <inertia
          ixx="1.29036276870304E-05"
          ixy="1.58818677610181E-22"
          ixz="-2.92042783707046E-22"
          iyy="1.29036276870304E-05"
          iyz="2.55939165719811E-22"
          izz="1.54277526418533E-05" />
      </inertial>
      <visual>
        <origin
          xyz="0 0 0"
          rpy="0 0 0" />
        <geometry>
          <mesh
            filename="$(find mason_description)/description/meshes/Wheel12.STL" />
        </geometry>
        <material
          name="">
          <color
            rgba="0.792156862745098 0.819607843137255 0.933333333333333 1" />
        </material>
      </visual>
      <collision>
        <origin
          xyz="0 0 0"
          rpy="0 0 0" />
        <geometry>
          <mesh
            filename="$(find mason_description)/description/meshes/Wheel12.STL" />
        </geometry>
      </collision>
    </link>
    <joint
      name="wheel12"
      type="fixed">
      <origin
        xyz="-0.0809981806109336 -0.140504689284423 0.0410000000000436"
        rpy="0 0 0.0384802682951065" />
      <parent
        link="ToolHeads" />
      <child
        link="Wheel12" />
      <axis
        xyz="0 0 -1" />
    </joint>
    <link
      name="Wheel11">
      <inertial>
        <origin
          xyz="-0.0951740034094164 -0.174564815982166 -3.77475828372553E-15"
          rpy="0 0 0" />
        <mass
          value="0.0529405486019685" />
        <inertia
          ixx="1.29036276870305E-05"
          ixy="-1.7205356741103E-22"
          ixz="-6.36103067152833E-20"
          iyy="1.29036276870305E-05"
          iyz="1.82982239530564E-22"
          izz="1.54277526418533E-05" />
      </inertial>
      <visual>
        <origin
          xyz="0 0 0"
          rpy="0 0 0" />
        <geometry>
          <mesh
            filename="$(find mason_description)/description/meshes/Wheel11.STL" />
        </geometry>
        <material
          name="">
          <color
            rgba="0.792156862745098 0.819607843137255 0.933333333333333 1" />
        </material>
      </visual>
      <collision>
        <origin
          xyz="0 0 0"
          rpy="0 0 0" />
        <geometry>
          <mesh
            filename="$(find mason_description)/description/meshes/Wheel11.STL" />
        </geometry>
      </collision>
    </link>
    <joint
      name="wheel11"
      type="fixed">
      <origin
        xyz="0.080998180609564 -0.140504689246202 0.0410000000000271"
        rpy="0 0 0.0119764103840232" />
      <parent
        link="ToolHeads" />
      <child
        link="Wheel11" />
      <axis
        xyz="0 0 1" />
    </joint>
    <link
      name="ServoRight">
      <inertial>
        <origin
          xyz="-0.0125039277122303 0.018036611987203 0.00075255651487071"
          rpy="0 0 0" />
        <mass
          value="0.00561881999310873" />
        <inertia
          ixx="1.18592135281841E-06"
          ixy="-2.74890920118256E-07"
          ixz="3.71529894726673E-09"
          iyy="5.28346112698774E-07"
          iyz="-3.49057653945542E-09"
          izz="1.66903397914588E-06" />
      </inertial>
      <visual>
        <origin
          xyz="0 0 0"
          rpy="0 0 0" />
        <geometry>
          <mesh
            filename="$(find mason_description)/description/meshes/ServoRight.STL" />
        </geometry>
        <material
          name="">
          <color
            rgba="0.898039215686275 0.917647058823529 0.929411764705882 1" />
        </material>
      </visual>
      <collision>
        <origin
          xyz="0 0 0"
          rpy="0 0 0" />
        <geometry>
          <mesh
            filename="$(find mason_description)/description/meshes/ServoRight.STL" />
        </geometry>
      </collision>
    </link>
    <joint
      name="Servo_Right"
      type="revolute">
      <origin
        xyz="-0.13708 -0.21773 0.1571"
        rpy="1.5708 0.80607 3.1416" />
      <parent
        link="ToolHeads" />
      <child
        link="ServoRight" />
      <axis
        xyz="0 0 -1" />
      <limit
        lower="0"
        upper="0.9"
        effort="1000"
        velocity="10" />
    </joint>
    <link
      name="ServoLeft">
      <inertial>
        <origin
          xyz="-0.00450603666586946 0.0233252877582936 0.000752560951625306"
          rpy="0 0 0" />
        <mass
          value="0.00561880872902954" />
        <inertia
          ixx="5.65412827180344E-07"
          ixy="3.23682891833923E-07"
          ixz="2.5512220579566E-11"
          iyy="1.14885269742664E-06"
          iyz="-5.09805124573721E-09"
          izz="1.66903217928846E-06" />
      </inertial>
      <visual>
        <origin
          xyz="0 0 0"
          rpy="0 0 0" />
        <geometry>
          <mesh
            filename="$(find mason_description)/description/meshes/ServoLeft.STL" />
        </geometry>
        <material
          name="">
          <color
            rgba="0.898039215686275 0.917647058823529 0.929411764705882 1" />
        </material>
      </visual>
      <collision>
        <origin
          xyz="0 0 0"
          rpy="0 0 0" />
        <geometry>
          <mesh
            filename="$(find mason_description)/description/meshes/ServoLeft.STL" />
        </geometry>
      </collision>
    </link>
    <joint
      name="Servo_Left"
      type="revolute">
      <origin
        xyz="-0.049077 -0.21773 0.1571"
        rpy="1.5708 -0.89849 3.1416" />
      <parent
        link="ToolHeads" />
      <child
        link="ServoLeft" />
      <axis
        xyz="0 0 -1" />
      <limit
        lower="0"
        upper="0.9"
        effort="1000"
        velocity="10" />
    </joint>
    <link
      name="ServoBottom">
      <inertial>
        <origin
          xyz="-0.00450603666658125 0.023325287763619 0.000752560950132208"
          rpy="0 0 0" />
        <mass
          value="0.005618808727496" />
        <inertia
          ixx="5.65412827159792E-07"
          ixy="3.23682891828456E-07"
          ixz="2.55122125522616E-11"
          iyy="1.14885269739886E-06"
          iyz="-5.09805124000953E-09"
          izz="1.66903217923596E-06" />
      </inertial>
      <visual>
        <origin
          xyz="0 0 0"
          rpy="0 0 0" />
        <geometry>
          <mesh
            filename="$(find mason_description)/description/meshes/ServoBottom.STL" />
        </geometry>
        <material
          name="">
          <color
            rgba="0.898039215686275 0.917647058823529 0.929411764705882 1" />
        </material>
      </visual>
      <collision>
        <origin
          xyz="0 0 0"
          rpy="0 0 0" />
        <geometry>
          <mesh
            filename="$(find mason_description)/description/meshes/ServoBottom.STL" />
        </geometry>
      </collision>
    </link>
    <joint
      name="Servo_Bottom"
      type="revolute">
      <origin
        xyz="-0.062212 -0.27169 0.1571"
        rpy="1.5708 -0.89849 1.5708" />
      <parent
        link="ToolHeads" />
      <child
        link="ServoBottom" />
      <axis
        xyz="0 0 -1" />
      <limit
        lower="0"
        upper="0.9"
        effort="1000"
        velocity="10" />
    </joint>
    <link
      name="BrushMotor">
      <inertial>
        <origin
          xyz="0.0128245774823816 -0.0205908954329129 -0.000437143179127353"
          rpy="0 0 0" />
        <mass
          value="0.0535429031362068" />
        <inertia
          ixx="1.12805507457558E-05"
          ixy="2.50153613303905E-12"
          ixz="-1.51332718657836E-06"
          iyy="1.17821919119883E-05"
          iyz="2.25497553435327E-14"
          izz="1.79670787823507E-05" />
      </inertial>
      <visual>
        <origin
          xyz="0 0 0"
          rpy="0 0 0" />
        <geometry>
          <mesh
            filename="$(find mason_description)/description/meshes/BrushMotor.STL" />
        </geometry>
        <material
          name="">
          <color
            rgba="0.776470588235294 0.756862745098039 0.737254901960784 1" />
        </material>
      </visual>
      <collision>
        <origin
          xyz="0 0 0"
          rpy="0 0 0" />
        <geometry>
          <mesh
            filename="$(find mason_description)/description/meshes/BrushMotor.STL" />
        </geometry>
      </collision>
    </link>
    <joint
      name="brushServo"
      type="prismatic">
      <origin
        xyz="-0.17282 -0.28489 0.13388"
        rpy="1.5708 1.5708 3.1416" />
      <parent
        link="ToolHeads" />
      <child
        link="BrushMotor" />
      <axis
        xyz="-1 0 0" />
      <limit
        lower="0"
        upper="0.02"
        effort="1000"
        velocity="10" />
    </joint>
    <link
      name="Brush">
      <inertial>
        <origin
          xyz="3.95741106551384E-10 -1.20338418174715E-07 -0.0100096641465032"
          rpy="0 0 0" />
        <mass
          value="3.2722316321584E-05" />
        <inertia
          ixx="1.05554049149581E-08"
          ixy="-5.46493901535366E-11"
          ixz="2.12759098988506E-16"
          iyy="1.04741181408134E-08"
          iyz="5.58810272964054E-15"
          izz="1.32165768160334E-08" />
      </inertial>
      <visual>
        <origin
          xyz="0 0 0"
          rpy="0 0 0" />
        <geometry>
          <mesh
            filename="$(find mason_description)/description/meshes/Brush.STL" />
        </geometry>
        <material
          name="">
          <color
            rgba="0.4 0.4 0.4 1" />
        </material>
      </visual>
      <collision>
        <origin
          xyz="0 0 0"
          rpy="0 0 0" />
        <geometry>
          <mesh
            filename="$(find mason_description)/description/meshes/Brush.STL" />
        </geometry>
      </collision>
    </link>
    <joint
      name="brushRotate"
      type="continuous">
      <origin
        xyz="-0.0241 -0.02075 -0.005"
        rpy="1.5708 0 1.5708" />
      <parent
        link="BrushMotor" />
      <child
        link="Brush" />
      <axis
        xyz="0 0 -1" />
    </joint>
    <link
      name="Extruder">
      <inertial>
        <origin
          xyz="-1.63753688942059E-07 0.0130139952768537 -0.0738167786593552"
          rpy="0 0 0" />
        <mass
          value="1.4653342959104" />
        <inertia
          ixx="0.00990394522385651"
          ixy="-1.14187865120943E-07"
          ixz="6.67476354130006E-08"
          iyy="0.00537452483444248"
          iyz="0.00058612134726128"
          izz="0.0105588970334041" />
      </inertial>
      <visual>
        <origin
          xyz="0 0 0"
          rpy="0 0 0" />
        <geometry>
          <mesh
            filename="$(find mason_description)/description/meshes/Extruder.STL" />
        </geometry>
        <material
          name="">
          <color
            rgba="0.647058823529412 0.619607843137255 0.588235294117647 1" />
        </material>
      </visual>
      <collision>
        <origin
          xyz="0 0 0"
          rpy="0 0 0" />
        <geometry>
          <mesh
            filename="$(find mason_description)/description/meshes/Extruder.STL" />
        </geometry>
      </collision>
    </link>
    <joint
      name="ExtruderJoint"
      type="fixed">
      <origin
        xyz="-0.0930765679814923 -0.107692112505467 0.0122585591987032"
        rpy="1.5707963267949 0 3.14159265358979" />
      <parent
        link="ToolHeads" />
      <child
        link="Extruder" />
      <axis
        xyz="0 0 0" />
    </joint>
    <link
      name="Camera">
      <inertial>
        <origin
          xyz="-8.27980192624755E-05 8.53850934621659E-05 -0.011411291537368"
          rpy="0 0 0" />
        <mass
          value="1.07236151786104" />
        <inertia
          ixx="0.000196647472960215"
          ixy="-1.12309565282472E-08"
          ixz="-4.16904656904137E-07"
          iyy="0.000196813120587306"
          iyz="2.96522497985688E-07"
          izz="0.000300205793594882" />
      </inertial>
      <visual>
        <origin
          xyz="0 0 0"
          rpy="0 0 0" />
        <geometry>
          <mesh
            filename="$(find mason_description)/description/meshes/Camera.STL" />
        </geometry>
        <material
          name="">
          <color
            rgba="1 0.941176470588235 0.67843137254902 1" />
        </material>
      </visual>
      <collision>
        <origin
          xyz="0 0 0"
          rpy="0 0 0" />
        <geometry>
          <mesh
            filename="$(find mason_description)/description/meshes/Camera.STL" />
        </geometry>
      </collision>
    </link>
    <joint
      name="CameraJoint"
      type="fixed">
      <origin
        xyz="0 0.133391440801338 -0.0528999999998068"
        rpy="1.5707963267949 0 3.14159265358979" />
      <parent
        link="Extruder" />
      <child
        link="Camera" />
      <axis
        xyz="0 0 0" />
    </joint>
    <link
      name="ExtruderLid">
      <inertial>
        <origin
          xyz="-6.38489261461928E-13 0.00200000000036211 -2.08166817117217E-14"
          rpy="0 0 0" />
        <mass
          value="0.170780246845705" />
        <inertia
          ixx="0.000630048831995056"
          ixy="1.94690366537566E-20"
          ixz="-2.0600960905604E-11"
          iyy="0.0012128343746113"
          iyz="-6.59159550628194E-22"
          izz="0.000583240956738759" />
      </inertial>
      <visual>
        <origin
          xyz="0 0 0"
          rpy="0 0 0" />
        <geometry>
          <mesh
            filename="$(find mason_description)/description/meshes/ExtruderLid.STL" />
        </geometry>
        <material
          name="">
          <color
            rgba="0.792156862745098 0.819607843137255 0.933333333333333 1" />
        </material>
      </visual>
      <collision>
        <origin
          xyz="0 0 0"
          rpy="0 0 0" />
        <geometry>
          <mesh
            filename="$(find mason_description)/description/meshes/ExtruderLid.STL" />
        </geometry>
      </collision>
    </link>
    <joint
      name="Extruderlid_Joint"
      type="fixed">
      <origin
        xyz="0 0 0"
        rpy="1.5707963267949 0 3.14159265358979" />
      <parent
        link="Extruder" />
      <child
        link="ExtruderLid" />
      <axis
        xyz="0 0 0" />
    </joint>
    <link
      name="Wheel10">
      <inertial>
        <origin
          xyz="-8.02455360578436E-05 1.55431223447522E-13 2.87159185319297E-13"
          rpy="0 0 0" />
        <mass
          value="0.210975435432665" />
        <inertia
          ixx="0.000195082527185753"
          ixy="9.2007802888537E-21"
          ixz="-2.74317892681988E-20"
          iyy="0.000123192117801239"
          iyz="1.28629488536281E-08"
          izz="0.000123167813160918" />
      </inertial>
      <visual>
        <origin
          xyz="0 0 0"
          rpy="0 0 0" />
        <geometry>
          <mesh
            filename="$(find mason_description)/description/meshes/Wheel10.STL" />
        </geometry>
        <material
          name="">
          <color
            rgba="0.792156862745098 0.819607843137255 0.933333333333333 1" />
        </material>
      </visual>
      <collision>
        <origin
          xyz="0 0 0"
          rpy="0 0 0" />
        <geometry>
          <mesh
            filename="$(find mason_description)/description/meshes/Wheel10.STL" />
        </geometry>
      </collision>
    </link>
    <joint
      name="wheel10"
      type="fixed">
      <origin
        xyz="-0.872317808532562 0.121108761586827 0.031000000000009"
        rpy="1.7742459074742 -1.5707963267949 0" />
      <parent
        link="WheelBracketTop" />
      <child
        link="Wheel10" />
      <axis
        xyz="0 0 0" />
    </joint>
    <link
      name="WheelHinge3Left">
      <inertial>
        <origin
          xyz="-0.0244751154928943 -0.200541156171973 -0.018727101068778"
          rpy="0 0 0" />
        <mass
          value="0.165316423881629" />
        <inertia
          ixx="0.000304272925724323"
          ixy="3.25327980907545E-05"
          ixz="2.40251206515421E-05"
          iyy="0.000222306193247368"
          iyz="-6.85580657075717E-05"
          izz="0.000154900041141416" />
      </inertial>
      <visual>
        <origin
          xyz="0 0 0"
          rpy="0 0 0" />
        <geometry>
          <mesh
            filename="$(find mason_description)/description/meshes/WheelHinge3Left.STL" />
        </geometry>
        <material
          name="">
          <color
            rgba="0.792156862745098 0.819607843137255 0.933333333333333 1" />
        </material>
      </visual>
      <collision>
        <origin
          xyz="0 0 0"
          rpy="0 0 0" />
        <geometry>
          <mesh
            filename="$(find mason_description)/description/meshes/WheelHinge3Left.STL" />
        </geometry>
      </collision>
    </link>
    <joint
      name="WH3L_HBT"
      type="fixed">
      <origin
        xyz="0.0409999999999148 -1.27900000000004 -0.085000000000387"
        rpy="-1.5707963267949 0 -1.5707963267949" />
      <parent
        link="Horizontal Bar Top" />
      <child
        link="WheelHinge3Left" />
      <axis
        xyz="0 0 0" />
    </joint>
    <link
      name="Wheel6">
      <inertial>
        <origin
          xyz="2.6104118866499E-14 -0.16716979718669 -0.0540553170848925"
          rpy="0 0 0" />
        <mass
          value="0.211779473167468" />
        <inertia
          ixx="0.000195048438274556"
          ixy="6.10726484580261E-19"
          ixz="-1.81051874316815E-18"
          iyy="0.000122863056698053"
          iyz="-6.7762635780344E-21"
          izz="0.000122863056698053" />
      </inertial>
      <visual>
        <origin
          xyz="0 0 0"
          rpy="0 0 0" />
        <geometry>
          <mesh
            filename="$(find mason_description)/description/meshes/Wheel6.STL" />
        </geometry>
        <material
          name="">
          <color
            rgba="0.792156862745098 0.819607843137255 0.933333333333333 1" />
        </material>
      </visual>
      <collision>
        <origin
          xyz="0 0 0"
          rpy="0 0 0" />
        <geometry>
          <mesh
            filename="$(find mason_description)/description/meshes/Wheel6.STL" />
        </geometry>
      </collision>
    </link>
    <joint
      name="wheel6"
      type="fixed">
      <origin
        xyz="0 0.00900000000001649 0.059999999999984"
        rpy="-0.312744023648199 0 0" />
      <parent
        link="WheelHinge3Left" />
      <child
        link="Wheel6" />
      <axis
        xyz="1 0 0" />
    </joint>
    <link
      name="Wheel7">
      <inertial>
        <origin
          xyz="-8.64586180426841E-15 0.102346514638857 -0.142803744131084"
          rpy="0 0 0" />
        <mass
          value="0.211779473167468" />
        <inertia
          ixx="0.000195048438274556"
          ixy="1.61069563197339E-18"
          ixz="1.11587729554219E-18"
          iyy="0.000122863056698053"
          iyz="-3.3881317890172E-21"
          izz="0.000122863056698054" />
      </inertial>
      <visual>
        <origin
          xyz="0 0 0"
          rpy="0 0 0" />
        <geometry>
          <mesh
            filename="$(find mason_description)/description/meshes/Wheel7.STL" />
        </geometry>
        <material
          name="">
          <color
            rgba="0.792156862745098 0.819607843137255 0.933333333333333 1" />
        </material>
      </visual>
      <collision>
        <origin
          xyz="0 0 0"
          rpy="0 0 0" />
        <geometry>
          <mesh
            filename="$(find mason_description)/description/meshes/Wheel7.STL" />
        </geometry>
      </collision>
    </link>
    <joint
      name="wheel7"
      type="fixed">
      <origin
        xyz="0 0.00899999999999779 -0.0599999999999828"
        rpy="0.948954313736275 0 3.14159265358979" />
      <parent
        link="WheelHinge3Left" />
      <child
        link="Wheel7" />
      <axis
        xyz="1 0 0" />
    </joint>
    <link
      name="WheelHinge1Left">
      <inertial>
        <origin
          xyz="-0.0150182712144254 -0.176153022928214 -0.0345338768293895"
          rpy="0 0 0" />
        <mass
          value="0.214742930836366" />
        <inertia
          ixx="0.000830775779814995"
          ixy="-3.28525561723034E-05"
          ixz="0.000115730835677916"
          iyy="0.000823146607327793"
          iyz="0.000146137364884107"
          izz="0.000149954007145533" />
      </inertial>
      <visual>
        <origin
          xyz="0 0 0"
          rpy="0 0 0" />
        <geometry>
          <mesh
            filename="$(find mason_description)/description/meshes/WheelHinge1Left.STL" />
        </geometry>
        <material
          name="">
          <color
            rgba="0.792156862745098 0.819607843137255 0.933333333333333 1" />
        </material>
      </visual>
      <collision>
        <origin
          xyz="0 0 0"
          rpy="0 0 0" />
        <geometry>
          <mesh
            filename="$(find mason_description)/description/meshes/WheelHinge1Left.STL" />
        </geometry>
      </collision>
    </link>
    <joint
      name="WH1L_HBB"
      type="fixed">
      <origin
        xyz="0.041 -1.279 0.038"
        rpy="-1.5708 0 -1.5708" />
      <parent
        link="Horizontal Bar Bottom" />
      <child
        link="WheelHinge1Left" />
      <axis
        xyz="0 0 0" />
    </joint>
    <link
      name="WheelHinge2Left">
      <inertial>
        <origin
          xyz="0.0916349501812297 -0.209102308485827 -0.0142586198156099"
          rpy="0 0 0" />
        <mass
          value="0.0812479952191667" />
        <inertia
          ixx="9.81601886330262E-05"
          ixy="-5.4311436207611E-05"
          ixz="1.96503798743729E-05"
          iyy="0.000116980843066376"
          iyz="1.65817814864411E-05"
          izz="0.000132008194876134" />
      </inertial>
      <visual>
        <origin
          xyz="0 0 0"
          rpy="0 0 0" />
        <geometry>
          <mesh
            filename="$(find mason_description)/description/meshes/WheelHinge2Left.STL" />
        </geometry>
        <material
          name="">
          <color
            rgba="0.792156862745098 0.819607843137255 0.933333333333333 1" />
        </material>
      </visual>
      <collision>
        <origin
          xyz="0 0 0"
          rpy="0 0 0" />
        <geometry>
          <mesh
            filename="$(find mason_description)/description/meshes/WheelHinge2Left.STL" />
        </geometry>
      </collision>
    </link>
    <joint
      name="WH2L_WH1L"
      type="fixed">
      <origin
        xyz="0.0210000000000393 0 0"
        rpy="0 1.5707963267949 0" />
      <parent
        link="WheelHinge1Left" />
      <child
        link="WheelHinge2Left" />
      <axis
        xyz="0 0 0" />
    </joint>
    <link
      name="Wheel9">
      <inertial>
        <origin
          xyz="-8.02455360653653E-05 -0.155815151831958 -0.0811748535949457"
          rpy="0 0 0" />
        <mass
          value="0.210975435432665" />
        <inertia
          ixx="0.000195082527185753"
          ixy="8.9844899051619E-19"
          ixz="-1.71008449154278E-18"
          iyy="0.000123165773734999"
          iyz="1.05701788868744E-08"
          izz="0.000123194157227159" />
      </inertial>
      <visual>
        <origin
          xyz="0 0 0"
          rpy="0 0 0" />
        <geometry>
          <mesh
            filename="$(find mason_description)/description/meshes/Wheel9.STL" />
        </geometry>
        <material
          name="">
          <color
            rgba="0.792156862745098 0.819607843137255 0.933333333333333 1" />
        </material>
      </visual>
      <collision>
        <origin
          xyz="0 0 0"
          rpy="0 0 0" />
        <geometry>
          <mesh
            filename="$(find mason_description)/description/meshes/Wheel9.STL" />
        </geometry>
      </collision>
    </link>
    <joint
      name="W9_WH2L"
      type="fixed">
      <origin
        xyz="0.0599999999999752 -0.0600000000001065 -0.0210000000000078"
        rpy="0.480281689634123 1.5707963267949 0" />
      <parent
        link="WheelHinge2Left" />
      <child
        link="Wheel9" />
      <axis
        xyz="1 0 0" />
    </joint>
    <link
      name="GearboxLeft">
      <inertial>
        <origin
          xyz="-1.16067155886412E-11 0.175684522130329 -0.0293276940792035"
          rpy="0 0 0" />
        <mass
          value="0.000256548604677884" />
        <inertia
          ixx="2.54736828036314E-07"
          ixy="6.40383187167488E-10"
          ixz="-1.42752427911235E-16"
          iyy="2.56149067715461E-07"
          iyz="-1.21078506822325E-10"
          izz="1.26043942390193E-07" />
      </inertial>
      <visual>
        <origin
          xyz="0 0 0"
          rpy="0 0 0" />
        <geometry>
          <mesh
            filename="$(find mason_description)/description/meshes/GearboxLeft.STL" />
        </geometry>
        <material
          name="">
          <color
            rgba="0.8 0.8 0.8 1" />
        </material>
      </visual>
      <collision>
        <origin
          xyz="0 0 0"
          rpy="0 0 0" />
        <geometry>
          <mesh
            filename="$(find mason_description)/description/meshes/GearboxLeft.STL" />
        </geometry>
      </collision>
    </link>
    <joint
      name="GBL_WH2L"
      type="fixed">
      <origin
        xyz="0.0599999999999773 -0.060000000000457 0.0814999999999902"
        rpy="0 0 3.14159265358979" />
      <parent
        link="WheelHinge2Left" />
      <child
        link="GearboxLeft" />
      <axis
        xyz="0 0 0" />
    </joint>
    <link
      name="Monteerplaatje Left">
      <inertial>
        <origin
          xyz="9.63118473862323E-13 0.176169492778003 0.0165014528780653"
          rpy="0 0 0" />
        <mass
          value="0.0317648196657452" />
        <inertia
          ixx="2.34438829670901E-05"
          ixy="2.32832074598379E-13"
          ixz="-9.64351754836971E-16"
          iyy="4.4049843145068E-05"
          iyz="6.22286701586465E-07"
          izz="3.2455074073778E-05" />
      </inertial>
      <visual>
        <origin
          xyz="0 0 0"
          rpy="0 0 0" />
        <geometry>
          <mesh
            filename="$(find mason_description)/description/meshes/Monteerplaatje Left.STL" />
        </geometry>
        <material
          name="">
          <color
            rgba="0.792156862745098 0.819607843137255 0.933333333333333 1" />
        </material>
      </visual>
      <collision>
        <origin
          xyz="0 0 0"
          rpy="0 0 0" />
        <geometry>
          <mesh
            filename="$(find mason_description)/description/meshes/Monteerplaatje Left.STL" />
        </geometry>
      </collision>
    </link>
    <joint
      name="MOPL_GBL"
      type="fixed">
      <origin
        xyz="0 0 0.022999999999996"
        rpy="0 0 0" />
      <parent
        link="GearboxLeft" />
      <child
        link="Monteerplaatje Left" />
      <axis
        xyz="0 0 0" />
    </joint>
    <link
      name="MotorLeft">
      <inertial>
        <origin
          xyz="0.13315017578423 -0.114631226289237 -0.0207593236548055"
          rpy="0 0 0" />
        <mass
          value="0.136603032784616" />
        <inertia
          ixx="5.81156919139382E-05"
          ixy="4.50109107887016E-10"
          ixz="5.00833005056809E-09"
          iyy="5.81194176757446E-05"
          iyz="4.20527442753521E-08"
          izz="6.65314608747261E-05" />
      </inertial>
      <visual>
        <origin
          xyz="0 0 0"
          rpy="0 0 0" />
        <geometry>
          <mesh
            filename="$(find mason_description)/description/meshes/MotorLeft.STL" />
        </geometry>
        <material
          name="">
          <color
            rgba="0.792156862745098 0.819607843137255 0.933333333333333 1" />
        </material>
      </visual>
      <collision>
        <origin
          xyz="0 0 0"
          rpy="0 0 0" />
        <geometry>
          <mesh
            filename="$(find mason_description)/description/meshes/MotorLeft.STL" />
        </geometry>
      </collision>
    </link>
    <joint
      name="MotorJointLeft"
      type="continuous">
      <origin
        xyz="0 0 0.010999999999996"
        rpy="-3.14159263675139 0 0.860036299777376" />
      <parent
        link="Monteerplaatje Left" />
      <child
        link="MotorLeft" />
      <axis
        xyz="-0.504967588524085 -0.323164363721622 -0.800357750359531" />
    </joint>
    <link
      name="Wheel8">
      <inertial>
        <origin
          xyz="1.6084356069257E-14 -0.167169797186631 -0.0540553170849143"
          rpy="0 0 0" />
        <mass
          value="0.211779473167468" />
        <inertia
          ixx="0.000195048438274556"
          ixy="-5.52828585847071E-19"
          ixz="1.77010014173781E-18"
          iyy="0.000122863056698054"
          iyz="1.01643953670516E-20"
          izz="0.000122863056698054" />
      </inertial>
      <visual>
        <origin
          xyz="0 0 0"
          rpy="0 0 0" />
        <geometry>
          <mesh
            filename="$(find mason_description)/description/meshes/Wheel8.STL" />
        </geometry>
        <material
          name="">
          <color
            rgba="0.792156862745098 0.819607843137255 0.933333333333333 1" />
        </material>
      </visual>
      <collision>
        <origin
          xyz="0 0 0"
          rpy="0 0 0" />
        <geometry>
          <mesh
            filename="$(find mason_description)/description/meshes/Wheel8.STL" />
        </geometry>
      </collision>
    </link>
    <joint
      name="W8_WH1L"
      type="fixed">
      <origin
        xyz="0 -0.0599999999999932 0.0600000000000001"
        rpy="-0.312744023648198 0 0" />
      <parent
        link="WheelHinge1Left" />
      <child
        link="Wheel8" />
      <axis
        xyz="1 0 0" />
    </joint>
    <link
      name="Horizontal Bar Connector Left">
      <inertial>
        <origin
          xyz="1.75970349403087E-14 -0.275692112504966 0.00999999999998144"
          rpy="0 0 0" />
        <mass
          value="0.0683596037592091" />
        <inertia
          ixx="0.000174202119847688"
          ixy="3.02888983392484E-18"
          ixz="2.5736521068554E-19"
          iyy="1.45830371947947E-05"
          iyz="5.16575875313627E-20"
          izz="0.000184227850125202" />
      </inertial>
      <visual>
        <origin
          xyz="0 0 0"
          rpy="0 0 0" />
        <geometry>
          <mesh
            filename="$(find mason_description)/description/meshes/Horizontal Bar Connector Left.STL" />
        </geometry>
        <material
          name="">
          <color
            rgba="0.792156862745098 0.819607843137255 0.933333333333333 1" />
        </material>
      </visual>
      <collision>
        <origin
          xyz="0 0 0"
          rpy="0 0 0" />
        <geometry>
          <mesh
            filename="$(find mason_description)/description/meshes/Horizontal Bar Connector Left.STL" />
        </geometry>
      </collision>
    </link>
    <joint
      name="HBCL_HBB"
      type="fixed">
      <origin
        xyz="0 -1.3 -0.2"
        rpy="-1.5708 0 0" />
      <parent
        link="Horizontal Bar Bottom" />
      <child
        link="Horizontal Bar Connector Left" />
      <axis
        xyz="0 0 0" />
    </joint>
    <link
      name="WheelHinge2Right">
      <inertial>
        <origin
          xyz="0.0916349501812439 -0.209102308485407 0.0142586198156596"
          rpy="0 0 0" />
        <mass
          value="0.0812479952191671" />
        <inertia
          ixx="9.81601886330248E-05"
          ixy="-5.43114362076122E-05"
          ixz="-1.96503798743711E-05"
          iyy="0.000116980843066376"
          iyz="-1.65817814864381E-05"
          izz="0.000132008194876137" />
      </inertial>
      <visual>
        <origin
          xyz="0 0 0"
          rpy="0 0 0" />
        <geometry>
          <mesh
            filename="$(find mason_description)/description/meshes/WheelHinge2Right.STL" />
        </geometry>
        <material
          name="">
          <color
            rgba="0.792156862745098 0.819607843137255 0.933333333333333 1" />
        </material>
      </visual>
      <collision>
        <origin
          xyz="0 0 0"
          rpy="0 0 0" />
        <geometry>
          <mesh
            filename="$(find mason_description)/description/meshes/WheelHinge2Right.STL" />
        </geometry>
      </collision>
    </link>
    <joint
      name="WH2R_WH1R"
      type="fixed">
      <origin
        xyz="0.021 0 0"
        rpy="0 -1.5708 0" />
      <parent
        link="WheelHinge1Right" />
      <child
        link="WheelHinge2Right" />
      <axis
        xyz="0 0 0" />
    </joint>
    <link
      name="Wheel3">
      <inertial>
        <origin
          xyz="-8.02455351429643E-05 -0.175204519271139 -0.0130803219912715"
          rpy="0 0 0" />
        <mass
          value="0.210975435432665" />
        <inertia
          ixx="0.000195082527185753"
          ixy="1.41585261921101E-19"
          ixz="-1.91005586802123E-18"
          iyy="0.000123165773734999"
          iyz="-1.05701788874072E-08"
          izz="0.000123194157227158" />
      </inertial>
      <visual>
        <origin
          xyz="0 0 0"
          rpy="0 0 0" />
        <geometry>
          <mesh
            filename="$(find mason_description)/description/meshes/Wheel3.STL" />
        </geometry>
        <material
          name="">
          <color
            rgba="0.792156862745098 0.819607843137255 0.933333333333333 1" />
        </material>
      </visual>
      <collision>
        <origin
          xyz="0 0 0"
          rpy="0 0 0" />
        <geometry>
          <mesh
            filename="$(find mason_description)/description/meshes/Wheel3.STL" />
        </geometry>
      </collision>
    </link>
    <joint
      name="wheel3"
      type="fixed">
      <origin
        xyz="0.0599999999999462 -0.0600000000001143 0.020999999999141"
        rpy="3.06707345216941 -1.5707963267949 0" />
      <parent
        link="WheelHinge2Right" />
      <child
        link="Wheel3" />
      <axis
        xyz="1 0 0" />
    </joint>
    <link
      name="GearboxRight">
      <inertial>
        <origin
          xyz="-4.296129840764E-10 -0.175684521373173 0.0293276986144608"
          rpy="0 0 0" />
        <mass
          value="0.000256548604677884" />
        <inertia
          ixx="2.54736828036315E-07"
          ixy="-6.4038318544179E-10"
          ixz="1.99333717357885E-15"
          iyy="2.56149067709211E-07"
          iyz="-1.21081873905765E-10"
          izz="1.26043942396443E-07" />
      </inertial>
      <visual>
        <origin
          xyz="0 0 0"
          rpy="0 0 0" />
        <geometry>
          <mesh
            filename="$(find mason_description)/description/meshes/GearboxRight.STL" />
        </geometry>
        <material
          name="">
          <color
            rgba="0.8 0.8 0.8 1" />
        </material>
      </visual>
      <collision>
        <origin
          xyz="0 0 0"
          rpy="0 0 0" />
        <geometry>
          <mesh
            filename="$(find mason_description)/description/meshes/GearboxRight.STL" />
        </geometry>
      </collision>
    </link>
    <joint
      name="GBR_WH2R"
      type="fixed">
      <origin
        xyz="0.059999999999986 -0.060000000000226 -0.0815000000008623"
        rpy="0 0 0" />
      <parent
        link="WheelHinge2Right" />
      <child
        link="GearboxRight" />
      <axis
        xyz="0 0 0" />
    </joint>
    <link
      name="Motorplaatje Right">
      <inertial>
        <origin
          xyz="9.67032010024127E-13 -0.176169493203443 -0.0165014483302954"
          rpy="0 0 0" />
        <mass
          value="0.0317648196657452" />
        <inertia
          ixx="2.34438829670901E-05"
          ixy="-2.32832443575727E-13"
          ixz="9.64281647794347E-16"
          iyy="4.404984317719E-05"
          iyz="6.22286402330464E-07"
          izz="3.24550740416562E-05" />
      </inertial>
      <visual>
        <origin
          xyz="0 0 0"
          rpy="0 0 0" />
        <geometry>
          <mesh
            filename="$(find mason_description)/description/meshes/Motorplaatje Right.STL" />
        </geometry>
        <material
          name="">
          <color
            rgba="0.792156862745098 0.819607843137255 0.933333333333333 1" />
        </material>
      </visual>
      <collision>
        <origin
          xyz="0 0 0"
          rpy="0 0 0" />
        <geometry>
          <mesh
            filename="$(find mason_description)/description/meshes/Motorplaatje Right.STL" />
        </geometry>
      </collision>
    </link>
    <joint
      name="MOPR_GBR"
      type="fixed">
      <origin
        xyz="0 0 -0.0229999999999999"
        rpy="0 0 0" />
      <parent
        link="GearboxRight" />
      <child
        link="Motorplaatje Right" />
      <axis
        xyz="0 0 0" />
    </joint>
    <link
      name="MotorRight">
      <inertial>
        <origin
          xyz="0.159365839081271 0.0739552187623284 -0.0207593236538715"
          rpy="0 0 0" />
        <mass
          value="0.136603032784615" />
        <inertia
          ixx="5.811569191394E-05"
          ixy="-4.50109115684801E-10"
          ixz="-5.00833013853344E-09"
          iyy="5.81194176757425E-05"
          iyz="4.20527442648723E-08"
          izz="6.6531460874726E-05" />
      </inertial>
      <visual>
        <origin
          xyz="0 0 0"
          rpy="0 0 0" />
        <geometry>
          <mesh
            filename="$(find mason_description)/description/meshes/MotorRight.STL" />
        </geometry>
        <material
          name="">
          <color
            rgba="0.792156862745098 0.819607843137255 0.933333333333333 1" />
        </material>
      </visual>
      <collision>
        <origin
          xyz="0 0 0"
          rpy="0 0 0" />
        <geometry>
          <mesh
            filename="$(find mason_description)/description/meshes/MotorRight.STL" />
        </geometry>
      </collision>
    </link>
    <joint
      name="MotorJointRight"
      type="continuous">
      <origin
        xyz="0 0 -0.0110000000000001"
        rpy="0 0 -2.0053236339767" />
      <parent
        link="Motorplaatje Right" />
      <child
        link="MotorRight" />
      <axis
        xyz="0 0 -1" />
    </joint>
    <link
      name="Wheel2">
      <inertial>
        <origin
          xyz="9.50794998288984E-13 0.0519129398764987 -0.167847445824451"
          rpy="0 0 0" />
        <mass
          value="0.211779473167468" />
        <inertia
          ixx="0.000195048438274556"
          ixy="-1.81230831323098E-18"
          ixz="-5.73673979286847E-19"
          iyy="0.000122863056698053"
          iyz="-1.01643953670516E-20"
          izz="0.000122863056698053" />
      </inertial>
      <visual>
        <origin
          xyz="0 0 0"
          rpy="0 0 0" />
        <geometry>
          <mesh
            filename="$(find mason_description)/description/meshes/Wheel2.STL" />
        </geometry>
        <material
          name="">
          <color
            rgba="0.792156862745098 0.819607843137255 0.933333333333333 1" />
        </material>
      </visual>
      <collision>
        <origin
          xyz="0 0 0"
          rpy="0 0 0" />
        <geometry>
          <mesh
            filename="$(find mason_description)/description/meshes/Wheel2.STL" />
        </geometry>
      </collision>
    </link>
    <joint
      name="wheel2"
      type="fixed">
      <origin
        xyz="0 -0.0600000000000248 -0.0599999999999793"
        rpy="1.27084178219794 0 3.14159265358979" />
      <parent
        link="WheelHinge1Right" />
      <child
        link="Wheel2" />
      <axis
        xyz="1 0 0" />
    </joint>

    <link name="camera_link">
    </link>

    <joint name="camera_link_to_camera" type="fixed">
      <parent link="Camera" />
      <child link="camera_link" />
      <origin xyz="0 0 0" rpy="3.14 -1.57 1.57" />
    </joint>

    <!-- TOF sensor -->
    <link name="tof_link">
      <visual>
        <origin xyz="0 0 0" rpy="0 0 0" />
        <geometry>
          <box size="0.05 0.05 0.05" />
        </geometry>
        <material name="">
          <color rgba="0.792156862745098 0.819607843137255 0.933333333333333 1" />
        </material>
      </visual>
      <inertial>
        <origin xyz="-6.38489261461928E-13 0.00200000000036211 -0.013"
          rpy="0 0 0" />
        <mass value="0.1" />
        <inertia ixx="0.001" iyy="0.001" izz="0.001" ixy="0" ixz="0" iyz="0" />
      </inertial>
    </link>

    <joint name="ExtruderLid_to_TOF" type="fixed">
      <parent link="ExtruderLid" />
      <child link="tof_link" />
      <origin xyz="-6.38489261461928E-13 0.00200000000036211 -0.013" rpy="0 0 0" />
    </joint>

    <!-- <frame name="lidar_frame" attached_to='chassis'>
        <pose>0.8 0 0.5 0 0 0</pose>
      </frame> -->

    <gazebo reference="tof_link">
        <sensor name="tof_sensor" type="gpu_lidar">
          <pose>0 0 0 1.570796 0 0</pose> <!-- Rotate 90 degrees (/2) about the X-axis -->
          <update_rate>10</update_rate>
          <topic>tof_sensor</topic>
          <ray>
            <scan>
              <horizontal>
                <samples>640</samples>
                <resolution>1</resolution>
                <min_angle>0</min_angle>
                <max_angle>0</max_angle>
              </horizontal>
              <vertical>
                <samples>1</samples>
                <resolution>0.01</resolution>
                <min_angle>-1.570796327</min_angle>
                <max_angle>1.570796327</max_angle>
              </vertical>
            </scan>
            <range>
              <min>0.01</min>
              <max>0.118</max>
              <resolution>0.01</resolution>
            </range>
          </ray>
          <always_on>1</always_on>
          <visualize>true</visualize>
        </sensor>
      </gazebo>



    <!-- Contact sensors bottom right -->
    <link name="contact_sensor_bottom_right">
      <visual>
        <origin xyz="0 0 0" rpy="0 0 0" />
        <geometry>
          <box size="0.05 0.05 0.05" />
        </geometry>
        <material name="">
          <color rgba="0.792156862745098 0.819607843137255 0.933333333333333 1" />
        </material>
      </visual>
      <collision name="Bottom Right Collision">
        <origin xyz="0 0 0" rpy="0 0 0" />
        <geometry>
          <box size="0.05 0.05 0.05" />
        </geometry>
      </collision>
      <inertial>
        <origin xyz="-1.34046800536292 -0.272459904837881 -0.3509903422149142"
          rpy="1.5707963267949 0 3.14159265358979" />
        <mass value="0.1" />
        <inertia ixx="0.001" iyy="0.001" izz="0.001" ixy="0" ixz="0" iyz="0" />
      </inertial>
    </link>

    <joint name="RightBar_to_BottomContactSensor" type="fixed">
      <parent link="RightBar" />
      <child link="contact_sensor_bottom_right" />
      <origin xyz="-1.34046800536292 -0.272459904837881 -0.3509903422149142"
        rpy="1.5707963267949 0 3.14159265358979" />
    </joint>

    <!-- Contact sensors top right -->
    <link name="contact_sensor_top_right">
      <visual>
        <origin xyz="0 0 0" rpy="0 0 0" />
        <geometry>
          <box size="0.05 0.05 0.05" />
        </geometry>
        <material name="">
          <color rgba="0.792156862745098 0.819607843137255 0.933333333333333 1" />
        </material>
      </visual>
      <collision name="Top Right Collision">
        <origin xyz="0 0 0" rpy="0 0 0" />
        <geometry>
          <box size="0.2 0.2 0.2" />
        </geometry>
      </collision>
      <inertial>
        <origin xyz="-1.34046800536292 -0.272459904837881 0.4490096577850858"
          rpy="1.5707963267949 0 3.14159265358979" />
        <mass value="0.1" />
        <inertia ixx="0.001" iyy="0.001" izz="0.001" ixy="0" ixz="0" iyz="0" />
      </inertial>
    </link>

    <joint name="RightBar_to_TopContactSensor" type="fixed">
      <parent link="RightBar" />
      <child link="contact_sensor_top_right" />
      <origin xyz="-1.34046800536292 -0.272459904837881 0.4490096577850858"
        rpy="1.5707963267949 0 3.14159265358979" />
    </joint>

    <!-- Contact sensors middle right -->
    <link name="contact_sensor_mid_right">
      <visual>
        <origin xyz="0 0 0"
          rpy="0 0 0" />
        <geometry>
          <box size="0.05 0.05 0.05" />
        </geometry>
        <material name="">
          <color rgba="0.792156862745098 0.819607843137255 0.933333333333333 1" />
        </material>
      </visual>
      <collision name="Middle Right Collision">
        <origin xyz="0 0 0"
          rpy="0 0 0" />
        <geometry>
          <box size="0.2 0.2 0.2" />
        </geometry>
      </collision>
      <inertial>
        <origin xyz="-1.32046800536292 -0.232459904837881 -0.0509903422149142"
          rpy="1.5707963267949 0 3.14159265358979" />
        <mass value="0.1" />
        <inertia ixx="0.001" iyy="0.001" izz="0.001" ixy="0" ixz="0" iyz="0" />
      </inertial>
    </link>

    <joint name="RightBar_to_MidContactSensor" type="fixed">
      <parent link="RightBar" />
      <child link="contact_sensor_mid_right" />
      <origin xyz="-1.32046800536292 -0.232459904837881 -0.0509903422149142"
        rpy="1.5707963267949 0 3.14159265358979" />
    </joint>

    <!-- Contact sensors bottom left -->
    <link name="contact_sensor_bottom_left">
      <visual>
        <origin xyz="0 0 0" rpy="0 0 0" />
        <geometry>
          <box size="0.05 0.05 0.05" />
        </geometry>
        <material name="">
          <color rgba="0.792156862745098 0.819607843137255 0.933333333333333 1" />
        </material>
      </visual>
      <collision name="Bottom Left Collision">
        <origin xyz="0 0 0" rpy="0 0 0" />
        <geometry>
          <box size="0.5 0.5 0.5" />
        </geometry>
      </collision>
      <inertial>
        <origin xyz="-0.08 -0.275692112504966 -0.39" rpy="1.5707963267949 0 3.14159265358979" />
        <mass value="0.1" />
        <inertia ixx="0.001" iyy="0.001" izz="0.001" ixy="0" ixz="0" iyz="0" />
      </inertial>
    </link>

    <joint name="LeftBar_to_BottomContactSensor" type="fixed">
      <parent link="RightBar" />
      <child link="contact_sensor_bottom_left" />
      <origin xyz="-0.08 -0.275692112504966 -0.39" rpy="1.5707963267949 0 3.14159265358979" />
    </joint>

    <!-- Contact sensors top left -->
    <link name="contact_sensor_top_left">
      <visual>
        <origin xyz="0 0 0" rpy="0 0 0" />
        <geometry>
          <box size="0.05 0.05 0.05" />
        </geometry>
        <material name="">
          <color rgba="0.792156862745098 0.819607843137255 0.933333333333333 1" />
        </material>
      </visual>
      <collision name="Top Left Collision">
        <origin xyz="0 0 0" rpy="0 0 0" />
        <geometry>
          <box size="0.2 0.2 0.2" />
        </geometry>
      </collision>
      <inertial>
        <origin xyz="-0.08 -0.275692112504966 0.40999999999998144"
          rpy="1.5707963267949 0 3.14159265358979" />
        <mass value="0.1" />
        <inertia ixx="0.001" iyy="0.001" izz="0.001" ixy="0" ixz="0" iyz="0" />
      </inertial>
    </link>

    <joint name="LeftBar_to_TopContactSensor" type="fixed">
      <parent link="RightBar" />
      <child link="contact_sensor_top_left" />
      <origin xyz="-0.08 -0.275692112504966 0.40999999999998144"
        rpy="1.5707963267949 0 3.14159265358979" />
    </joint>

    <!-- Contact sensors middle left -->
    <link name="contact_sensor_mid_left">
      <visual>
        <origin xyz="0 0 0"
          rpy="0 0 0" />
        <geometry>
          <box size="0.05 0.05 0.05" />
        </geometry>
        <material name="">
          <color rgba="0.792156862745098 0.819607843137255 0.933333333333333 1" />
        </material>
      </visual>
      <collision name="Middle Left Collision">
        <origin xyz="0 0 0"
          rpy="0 0 0" />
        <geometry>
          <box size="0.2 0.2 0.2" />
        </geometry>
      </collision>
      <inertial>
        <origin xyz="-0.1 -0.235692112504966 0.00999999999998144"
          rpy="0 0 0" />
        <mass value="0.1" />
        <inertia ixx="0.001" iyy="0.001" izz="0.001" ixy="0" ixz="0" iyz="0" />
      </inertial>
    </link>

    <joint name="LeftBar_to_MidContactSensor" type="fixed">
      <parent link="RightBar" />
      <child link="contact_sensor_mid_left" />
      <origin xyz="-0.1 -0.235692112504966 0.00999999999998144"
        rpy="0 0 0" />
    </joint>

    <gazebo reference="contact_sensor_bottom_right">
      <sensor name="bottom_right_contact_sensor" type="contact">
        <collision>Bottom Right Collision</collision>
      </sensor>
    </gazebo>

    <gazebo reference="contact_sensor_top_right">
      <sensor name="top_right_contact_sensor" type="contact">
        <collision>Top Right Collision</collision>
      </sensor>
    </gazebo>

    <gazebo reference="contact_sensor_mid_right">
      <sensor name="mid_right_contact_sensor" type="contact">
        <collision>Middle Right Collision</collision>
      </sensor>
    </gazebo>

    <gazebo reference="contact_sensor_bottom_left">
      <sensor name="bottom_left_contact_sensor" type="contact">
        <collision>Bottom Left Collision</collision>
      </sensor>
    </gazebo>

    <gazebo reference="contact_sensor_top_left">
      <sensor name="top_left_contact_sensor" type="contact">
        <collision>Top Left Collision</collision>
      </sensor>
    </gazebo>

    <gazebo reference="contact_sensor_mid_left">
      <sensor name="mid_left_contact_sensor" type="contact">
        <collision>Middle Left Collision</collision>
      </sensor>
    </gazebo>

    <link name="imu_link"></link>


    <joint name="gearbox_to_imu" type="fixed">
      <parent link="WheelBracketTop" />
      <child link="imu_link"></child>
    </joint>

    <gazebo reference="imu_link">
      <sensor name="gearbox_imu" type="imu">
        <always_on>1</always_on>
        <update_rate>10.0</update_rate>
        <visualize>true</visualize>
        <topic>imu</topic>
      </sensor>
    </gazebo>

    <gazebo reference="camera_link">
      <sensor name="rgbd_camera" type="rgbd_camera">
        <camera>
          <horizontal_fov>1.5</horizontal_fov>
          <image>
            <width>840</width>
            <height>480</height>
          </image>
          <clip>
            <near>0.001</near>
            <far>100</far>
          </clip>
        </camera>
        <always_on>1</always_on>
        <update_rate>30</update_rate>
        <visualize>true</visualize>
        <topic>rgbd_camera</topic>
        <enable_metrics>true</enable_metrics>
      </sensor>
    </gazebo>


    <gazebo>
      <plugin filename="gz_ros2_control-system" name="gz_ros2_control::GazeboSimROS2ControlPlugin">
        <parameters>$(find mason_description)/description/config/mason.yaml</parameters>
      </plugin>
    </gazebo>

  </xacro:macro>

</robot>