<?xml version="1.0"?>
<robot name="mason" xmlns:xacro="http://ros.org/wiki/xacro">

  <link name="world" />

  <link
    name="RightBar">
    <inertial>
      <origin
        xyz="-1.34046800536385 -0.272459904837881 0.0490096577850493"
        rpy="0 0 0" />
      <mass
        value="5.55312910017423" />
      <inertia
        ixx="0.782838152186612"
        ixy="1.1967535365083E-17"
        ixz="3.18583569221935E-19"
        iyy="0.782838152186612"
        iyz="-4.85401392836333E-17"
        izz="0.00154494115749391" />
    </inertial>
    <visual>
      <origin
        xyz="0 0 0"
        rpy="0 0 0" />
      <geometry>
        <mesh
          filename="$(find gz_ros2_control_demos)/meshes/RightBar.STL" />
      </geometry>
      <material
        name="">
        <color
          rgba="0.647058823529412 0.619607843137255 0.588235294117647 1" />
      </material>
    </visual>
    <collision name="Right Bar Collision">
      <origin
        xyz="0 0 0"
        rpy="0 0 0" />
      <geometry>
        <mesh
          filename="$(find gz_ros2_control_demos)/meshes/RightBar.STL" />
      </geometry>
    </collision>
  </link>

  <joint name="world_to_rightBar" type="fixed">
    <origin rpy="0 0 0" xyz="0 0 0" />
    <parent link="world" />
    <child link="RightBar" />
  </joint>

  <link
    name="RightBracketTop">
    <inertial>
      <origin
        xyz="-0.0307068750966646 0.0431985153100421 -6.29781427896603E-07"
        rpy="0 0 0" />
      <mass
        value="0.000214749814862542" />
      <inertia
        ixx="5.04014900228217E-07"
        ixy="1.41838418654997E-07"
        ixz="-1.26884313972509E-12"
        iyy="2.49863376560335E-07"
        iyz="4.0620265603021E-12"
        izz="5.24669847054164E-07" />
    </inertial>
    <visual>
      <origin
        xyz="0 0 0"
        rpy="0 0 0" />
      <geometry>
        <mesh
          filename="$(find gz_ros2_control_demos)/meshes/RightBracketTop.STL" />
      </geometry>
      <material
        name="">
        <color
          rgba="0.4 0.4 0.4 1" />
      </material>
    </visual>
    <collision>
      <origin
        xyz="0 0 0"
        rpy="0 0 0" />
      <geometry>
        <mesh
          filename="$(find gz_ros2_control_demos)/meshes/RightBracketTop.STL" />
      </geometry>
    </collision>
  </link>
  <joint
    name="RBT_RB"
    type="fixed">
    <origin
      xyz="-1.43796800536526 -0.392459904838281 0.589966540848759"
      rpy="-3.14159265358979 0 3.14159265358979" />
    <parent
      link="RightBar" />
    <child
      link="RightBracketTop" />
    <axis
      xyz="0 0 0" />
  </joint>
  <link
    name="RightBracketBottom">
    <inertial>
      <origin
        xyz="-0.0307095280162772 0.0432034395198194 4.98524199366024E-07"
        rpy="0 0 0" />
      <mass
        value="0.2147695030834" />
      <inertia
        ixx="0.000504017787094401"
        ixy="0.000141840084805532"
        ixz="-2.55519874231157E-09"
        iyy="0.000249864733012358"
        iyz="5.55018450228669E-09"
        izz="0.00052467325043935" />
    </inertial>
    <visual>
      <origin
        xyz="0 0 0"
        rpy="0 0 0" />
      <geometry>
        <mesh
          filename="file:///home/lsitanyi/Robot_Assembly_URDF/meshes/RightBracketBottom.STL" />
      </geometry>
      <material
        name="">
        <color
          rgba="0.792156862745098 0.819607843137255 0.933333333333333 1" />
      </material>
    </visual>
    <collision>
      <origin
        xyz="0 0 0"
        rpy="0 0 0" />
      <geometry>
        <mesh
          filename="file:///home/lsitanyi/Robot_Assembly_URDF/meshes/RightBracketBottom.STL" />
      </geometry>
    </collision>
  </link>
  <joint
    name="RBB_RB"
    type="fixed">
    <origin
      xyz="-1.43796800536388 -0.392459904837929 -0.437021328543411"
      rpy="-3.14159265358979 0 3.14159265358979" />
    <parent
      link="RightBar" />
    <child
      link="RightBracketBottom" />
    <axis
      xyz="0 0 0" />
  </joint>



  <link
    name="LeftBar">
    <inertial>
      <origin
        xyz="6.93889390390723E-17 0.65 5.55111512312578E-17"
        rpy="0 0 0" />
      <mass
        value="5.55312910017433" />
      <inertia
        ixx="0.782838152186633"
        ixy="-3.84480360700147E-18"
        ixz="-1.03281357693064E-17"
        iyy="0.00154494115749394"
        iyz="-1.94626228426361E-18"
        izz="0.782838152186633" />
    </inertial>
    <visual>
      <origin
        xyz="0 0 0"
        rpy="0 0 0" />
      <geometry>
        <mesh
          filename="file:///home/lsitanyi/Robot_Assembly_URDF/meshes/LeftBar.STL" />
      </geometry>
      <material
        name="">
        <color
          rgba="0.647058823529412 0.619607843137255 0.588235294117647 1" />
      </material>
    </visual>
    <collision>
      <origin
        xyz="0 0 0"
        rpy="0 0 0" />
      <geometry>
        <mesh
          filename="file:///home/lsitanyi/Robot_Assembly_URDF/meshes/LeftBar.STL" />
      </geometry>
    </collision>
  </link>
  <joint
    name="LB_RB"
    type="fixed">
    <origin
      xyz="-0.0824680053628981 -0.272459904837888 -0.600990342214936"
      rpy="1.5707963267949 0 0" />
    <parent
      link="RightBar" />
    <child
      link="LeftBar" />
    <axis
      xyz="0 0 0" />
  </joint>
  <link
    name="LeftBracketTop">
    <inertial>
      <origin
        xyz="-0.0307068750966565 0.0431985153100043 -6.29781428118648E-07"
        rpy="0 0 0" />
      <mass
        value="0.000214749814862542" />
      <inertia
        ixx="5.04014900228218E-07"
        ixy="1.41838418654999E-07"
        ixz="-1.26884314001887E-12"
        iyy="2.49863376560336E-07"
        iyz="4.06202656011104E-12"
        izz="5.24669847054166E-07" />
    </inertial>
    <visual>
      <origin
        xyz="0 0 0"
        rpy="0 0 0" />
      <geometry>
        <mesh
          filename="file:///home/lsitanyi/Robot_Assembly_URDF/meshes/LeftBracketTop.STL" />
      </geometry>
      <material
        name="">
        <color
          rgba="0.4 0.4 0.4 1" />
      </material>
    </visual>
    <collision>
      <origin
        xyz="0 0 0"
        rpy="0 0 0" />
      <geometry>
        <mesh
          filename="file:///home/lsitanyi/Robot_Assembly_URDF/meshes/LeftBracketTop.STL" />
      </geometry>
    </collision>
  </link>
  <joint
    name="LBT_LB"
    type="fixed">
    <origin
      xyz="0.0975000000014027 1.1909568830637 0.120000000000417"
      rpy="-1.5707963267949 0 0" />
    <parent
      link="LeftBar" />
    <child
      link="LeftBracketTop" />
    <axis
      xyz="0 0 0" />
  </joint>
  <link
    name="LeftBracketBottom">
    <inertial>
      <origin
        xyz="-0.0307068750986306 0.0431985153105867 -6.29781428063136E-07"
        rpy="0 0 0" />
      <mass
        value="0.000214749814862542" />
      <inertia
        ixx="5.04014900228219E-07"
        ixy="1.41838418654999E-07"
        ixz="-1.26884313989582E-12"
        iyy="2.49863376560336E-07"
        iyz="4.06202655981643E-12"
        izz="5.24669847054167E-07" />
    </inertial>
    <visual>
      <origin
        xyz="0 0 0"
        rpy="0 0 0" />
      <geometry>
        <mesh
          filename="file:///home/lsitanyi/Robot_Assembly_URDF/meshes/LeftBracketBottom.STL" />
      </geometry>
      <material
        name="">
        <color
          rgba="0.4 0.4 0.4 1" />
      </material>
    </visual>
    <collision>
      <origin
        xyz="0 0 0"
        rpy="0 0 0" />
      <geometry>
        <mesh
          filename="file:///home/lsitanyi/Robot_Assembly_URDF/meshes/LeftBracketBottom.STL" />
      </geometry>
    </collision>
  </link>
  <joint
    name="LBB_LB"
    type="fixed">
    <origin
      xyz="0.0974999999999891 0.163969013671525 0.12"
      rpy="-1.5707963267949 0 0" />
    <parent
      link="LeftBar" />
    <child
      link="LeftBracketBottom" />
    <axis
      xyz="0 0 0" />
  </joint>


  <link
    name="WheelHinge1Right">
    <inertial>
      <origin
        xyz="-0.0150182712144464 -0.000460910423413164 0.034533876829339"
        rpy="0 0 0" />
      <mass
        value="0.214742930836365" />
      <inertia
        ixx="0.000830775779814993"
        ixy="-3.28525561723032E-05"
        ixz="-0.000115730835677916"
        iyy="0.000823146607327791"
        iyz="-0.000146137364884107"
        izz="0.000149954007145533" />
    </inertial>
    <visual>
      <origin
        xyz="0 0 0"
        rpy="0 0 0" />
      <geometry>
        <mesh
          filename="file:///home/lsitanyi/Robot_Assembly_URDF/meshes/WheelHinge1Right.STL" />
      </geometry>
      <material
        name="">
        <color
          rgba="0.792156862745098 0.819607843137255 0.933333333333333 1" />
      </material>
    </visual>
    <collision>
      <origin
        xyz="0 0 0"
        rpy="0 0 0" />
      <geometry>
        <mesh
          filename="file:///home/lsitanyi/Robot_Assembly_URDF/meshes/WheelHinge1Right.STL" />
      </geometry>
    </collision>
  </link>
  <!-- slider up down-->
  <joint
    name="slider"
    type="prismatic">
    <origin
      xyz="-1.3405 -0.27246 0.022736"
      rpy="1.5708 0 3.1416" />
    <parent
      link="RightBar" />
    <child
      link="WheelHinge1Right" />
    <axis
      xyz="0 1 0" />
    <limit
      lower="-0.4"
      upper="0.2"
      effort="1000"
      velocity="0.03" />
  </joint>

  <link
    name="Horizontal Bar Bottom">
    <inertial>
      <origin
        xyz="-1.68476343986868E-14 -0.650000000000009 5.05200048461774E-13"
        rpy="0 0 0" />
      <mass
        value="5.55312910017435" />
      <inertia
        ixx="0.782838152186633"
        ixy="-2.0488993550812E-14"
        ixz="1.01067718976296E-17"
        iyy="0.00154494115749394"
        iyz="2.07187005799898E-17"
        izz="0.782838152186633" />
    </inertial>
    <visual>
      <origin
        xyz="0 0 0"
        rpy="0 0 0" />
      <geometry>
        <mesh
          filename="file:///home/lsitanyi/Robot_Assembly_URDF/meshes/Horizontal Bar Bottom.STL" />
      </geometry>
      <material
        name="">
        <color
          rgba="0.647058823529412 0.619607843137255 0.588235294117647 1" />
      </material>
    </visual>
    <collision>
      <origin
        xyz="0 0 0"
        rpy="0 0 0" />
      <geometry>
        <mesh
          filename="file:///home/lsitanyi/Robot_Assembly_URDF/meshes/Horizontal Bar Bottom.STL" />
      </geometry>
    </collision>
  </link>

  <joint
    name="HBB_WH1R"
    type="fixed">
    <origin
      xyz="0.021 0.038 0.041"
      rpy="1.5708 1.5708 0" />
    <parent
      link="WheelHinge1Right" />
    <child
      link="Horizontal Bar Bottom" />
    <axis
      xyz="0 0 0" />
  </joint>

  <link
    name="Horizontal Bar Connector">
    <inertial>
      <origin
        xyz="-3.10584891138888E-14 -0.100000000000506 -0.00999999999999446"
        rpy="0 0 0" />
      <mass
        value="0.0683596037592092" />
      <inertia
        ixx="0.000174202119847688"
        ixy="3.0318326454746E-18"
        ixz="2.42938730807149E-19"
        iyy="1.45830371947947E-05"
        iyz="6.78353621262493E-20"
        izz="0.000184227850125202" />
    </inertial>
    <visual>
      <origin
        xyz="0 0 0"
        rpy="0 0 0" />
      <geometry>
        <mesh
          filename="file:///home/lsitanyi/Robot_Assembly_URDF/meshes/Horizontal Bar Connector.STL" />
      </geometry>
      <material
        name="">
        <color
          rgba="0.792156862745098 0.819607843137255 0.933333333333333 1" />
      </material>
    </visual>
    <collision>
      <origin
        xyz="0 0 0"
        rpy="0 0 0" />
      <geometry>
        <mesh
          filename="file:///home/lsitanyi/Robot_Assembly_URDF/meshes/Horizontal Bar Connector.STL" />
      </geometry>
    </collision>
  </link>
  <joint
    name="HBC_HBB"
    type="fixed">
    <origin
      xyz="0 0 -0.200000000000012"
      rpy="-1.5707963267949 0 0" />
    <parent
      link="Horizontal Bar Bottom" />
    <child
      link="Horizontal Bar Connector" />
    <axis
      xyz="0 0 0" />
  </joint>

  <link
    name="Horizontal Bar Top">
    <inertial>
      <origin
        xyz="-7.22477633274821E-14 -0.650000000000058 4.94437824016813E-13"
        rpy="0 0 0" />
      <mass
        value="5.55312910017435" />
      <inertia
        ixx="0.782838152186633"
        ixy="-2.04724933564449E-14"
        ixz="1.09456674556079E-17"
        iyy="0.00154494115749394"
        iyz="1.76050052863536E-17"
        izz="0.782838152186633" />
    </inertial>
    <visual>
      <origin
        xyz="0 0 0"
        rpy="0 0 0" />
      <geometry>
        <mesh
          filename="file:///home/lsitanyi/Robot_Assembly_URDF/meshes/Horizontal Bar Top.STL" />
      </geometry>
      <material
        name="">
        <color
          rgba="0.647058823529412 0.619607843137255 0.588235294117647 1" />
      </material>
    </visual>
    <collision>
      <origin
        xyz="0 0 0"
        rpy="0 0 0" />
      <geometry>
        <mesh
          filename="file:///home/lsitanyi/Robot_Assembly_URDF/meshes/Horizontal Bar Top.STL" />
      </geometry>
    </collision>
  </link>
  <joint
    name="HBT_HBC"
    type="fixed">
    <origin
      xyz="0 0 0"
      rpy="1.5707963267949 0 0" />
    <parent
      link="Horizontal Bar Connector" />
    <child
      link="Horizontal Bar Top" />
    <axis
      xyz="0 0 0" />
  </joint>
  <link
    name="WheelHinge3Right">
    <inertial>
      <origin
        xyz="-0.0244751154928602 -0.0248490436670661 0.0187271010688276"
        rpy="0 0 0" />
      <mass
        value="0.165316423881629" />
      <inertia
        ixx="0.000304272925724323"
        ixy="3.25327980907543E-05"
        ixz="-2.40251206515419E-05"
        iyy="0.000222306193247368"
        iyz="6.85580657075716E-05"
        izz="0.000154900041141416" />
    </inertial>
    <visual>
      <origin
        xyz="0 0 0"
        rpy="0 0 0" />
      <geometry>
        <mesh
          filename="file:///home/lsitanyi/Robot_Assembly_URDF/meshes/WheelHinge3Right.STL" />
      </geometry>
      <material
        name="">
        <color
          rgba="0.792156862745098 0.819607843137255 0.933333333333333 1" />
      </material>
    </visual>
    <collision>
      <origin
        xyz="0 0 0"
        rpy="0 0 0" />
      <geometry>
        <mesh
          filename="file:///home/lsitanyi/Robot_Assembly_URDF/meshes/WheelHinge3Right.STL" />
      </geometry>
    </collision>
  </link>
  <joint
    name="WH3R_HBT"
    type="fixed">
    <origin
      xyz="0.0409999999999521 -0.0209999999999979 -0.0849999999998929"
      rpy="-1.5707963267949 0 1.5707963267949" />
    <parent
      link="Horizontal Bar Top" />
    <child
      link="WheelHinge3Right" />
    <axis
      xyz="0 0 0" />
  </joint>

  <link
    name="Wheel4">
    <inertial>
      <origin
        xyz="-2.39808173319034E-14 3.61405350091104E-13 5.04263297784746E-13"
        rpy="0 0 0" />
      <mass
        value="0.211779473167468" />
      <inertia
        ixx="0.000195048438274556"
        ixy="1.60935517073852E-18"
        ixz="-1.1214478783478E-18"
        iyy="0.000122863056698053"
        iyz="-1.35525271560688E-20"
        izz="0.000122863056698054" />
    </inertial>
    <visual>
      <origin
        xyz="0 0 0"
        rpy="0 0 0" />
      <geometry>
        <mesh
          filename="file:///home/lsitanyi/Robot_Assembly_URDF/meshes/Wheel4.STL" />
      </geometry>
      <material
        name="">
        <color
          rgba="0.792156862745098 0.819607843137255 0.933333333333333 1" />
      </material>
    </visual>
    <collision>
      <origin
        xyz="0 0 0"
        rpy="0 0 0" />
      <geometry>
        <mesh
          filename="file:///home/lsitanyi/Robot_Assembly_URDF/meshes/Wheel4.STL" />
      </geometry>
    </collision>
  </link>
  <joint
    name="wheel4"
    type="continuous">
    <origin
      xyz="0 0.00900000000021645 0.0600000000000486"
      rpy="-0.948954313736275 0 3.14159265358979" />
    <parent
      link="WheelHinge3Right" />
    <child
      link="Wheel4" />
    <axis
      xyz="1 0 0" />
  </joint>
  <link
    name="Wheel5">
    <inertial>
      <origin
        xyz="3.66373598126302E-14 -6.41653397082109E-13 2.06057393370429E-13"
        rpy="0 0 0" />
      <mass
        value="0.211779473167469" />
      <inertia
        ixx="0.000195048438274556"
        ixy="-5.5621578568884E-19"
        ixz="-1.78278698033902E-18"
        iyy="0.000122863056698054"
        iyz="-1.6940658945086E-20"
        izz="0.000122863056698054" />
    </inertial>
    <visual>
      <origin
        xyz="0 0 0"
        rpy="0 0 0" />
      <geometry>
        <mesh
          filename="file:///home/lsitanyi/Robot_Assembly_URDF/meshes/Wheel5.STL" />
      </geometry>
      <material
        name="">
        <color
          rgba="0.792156862745098 0.819607843137255 0.933333333333333 1" />
      </material>
    </visual>
    <collision>
      <origin
        xyz="0 0 0"
        rpy="0 0 0" />
      <geometry>
        <mesh
          filename="file:///home/lsitanyi/Robot_Assembly_URDF/meshes/Wheel5.STL" />
      </geometry>
    </collision>
  </link>
  <joint
    name="wheel5"
    type="continuous">
    <origin
      xyz="0 0.00900000000028894 -0.0599999999999917"
      rpy="0.312744023648199 0 0" />
    <parent
      link="WheelHinge3Right" />
    <child
      link="Wheel5" />
    <axis
      xyz="1 0 0" />
  </joint>
  <link
    name="WheelBracketTop">
    <inertial>
      <origin
        xyz="-0.779305338920871 0.302052976421749 0.0316973524931664"
        rpy="0 0 0" />
      <mass
        value="0.240740698245303" />
      <inertia
        ixx="0.000663222771568811"
        ixy="-8.08191067052128E-07"
        ixz="-1.07609063234527E-08"
        iyy="0.000252811429413381"
        iyz="2.37785454057657E-07"
        izz="0.000647287300412066" />
    </inertial>
    <visual>
      <origin
        xyz="0 0 0"
        rpy="0 0 0" />
      <geometry>
        <mesh
          filename="file:///home/lsitanyi/Robot_Assembly_URDF/meshes/WheelBracketTop.STL" />
      </geometry>
      <material
        name="">
        <color
          rgba="0.792156862745098 0.819607843137255 0.933333333333333 1" />
      </material>
    </visual>
    <collision>
      <origin
        xyz="0 0 0"
        rpy="0 0 0" />
      <geometry>
        <mesh
          filename="file:///home/lsitanyi/Robot_Assembly_URDF/meshes/WheelBracketTop.STL" />
      </geometry>
    </collision>
  </link>
  <joint
    name="slider2"
    type="prismatic">
    <origin
      xyz="-0.031000000000083 -1.44312518930694 0.236800874091782"
      rpy="-1.5707963267949 0 -1.5707963267949" />
    <parent
      link="Horizontal Bar Top" />
    <child
      link="WheelBracketTop" />
    <axis
      xyz="1 0 0" />
    <limit
      lower="-0.4"
      upper="0.4"
      effort="1000"
      velocity="0.1" />
  </joint>

  <!-- <link name="camera_frame_link"></link>
  <link name="camera_link"></link>
  <joint
    name="HBT_to_camera_link"
    type="fixed">
    <parent
      link="Horizontal Bar Top" />
    <child
      link="camera_link" />
    <origin
      xyz="-7.22477633274821E-14 -0.650000000000058 4.94437824016813E-13"
      rpy="0 0 1.5707963267949" />
  </joint> -->

  <link name="imu_link">
    <inertial>
      <mass value="0.1"/>
      <inertia ixx="1.0" ixy="0" ixz="0" iyy="1.0" iyz="0" izz="1.0"/>
    </inertial>
  </link>
  <joint name="HBT_to_imu" type="fixed">
    <parent link="Horizontal Bar Top" />
    <child link="imu_link" />
    <origin xyz="-7.22477633274821E-14 -0.650000000000058 4.94437824016813E-13" rpy="0 0 0" />
  </joint>

  <!-- <joint name="camera_link_to_camera_frame_link" type="fixed">
    <parent link="camera_link" />
    <child link="camera_frame_link" />
    <origin xyz="0 0 0" rpy="-1.570796327 0 -1.570796327" />
  </joint>

  <gazebo reference="camera_link">
    <sensor name="depth_camera" type="depth_camera">
    <pose>0 0 0 0 0 0</pose>
      <visualize>true</visualize>
      <update_rate>90</update_rate>
      <camera>
        <horizontal_fov>1.4661</horizontal_fov>
        <image>
          <format>R8G8B8</format>
          <width>848</width>
          <height>480</height>
        </image>
        <clip>
          <near>0.07</near>
          <far>0.5</far>
        </clip>
      </camera>
    </sensor>
  </gazebo> -->

  <gazebo reference="imu_link">
    <sensor name="imu_sensor" type="imu">
      <update_rate>100</update_rate>
      <!-- <plugin name="gazebo_ros_imu" filename="libgazebo_ros_imu.so" /> -->
      <visualize>true</visualize>
      <topic>imu</topic>
    </sensor>
  </gazebo>

  <gazebo reference="RightBar">
    <sensor name="end_of_frame_sensor" type="contact">
      <collision>Right Bar Collision</collision>
    </sensor>
  </gazebo>

  <ros2_control name="GazeboSimSystem" type="system">
    <hardware>
      <plugin>gz_ros2_control/GazeboSimSystem</plugin>
    </hardware>
    <joint name="slider">
      <command_interface name="velocity">
        <param name="min">-0.1</param>
        <param name="max">0.1</param>
      </command_interface>
      <state_interface name="position" />
      <state_interface name="velocity" />
      <state_interface name="effort" />
    </joint>
    <joint name="slider2">
      <command_interface name="velocity">
        <param name="min">-0.1</param>
        <param name="max">0.1</param>
      </command_interface>
      <state_interface name="position" />
      <state_interface name="velocity" />
      <state_interface name="effort" />
    </joint>
    <sensor name="imu_sensor">
      <state_interface name="orientation.x"/>
      <state_interface name="orientation.y"/>
      <state_interface name="orientation.z"/>
      <state_interface name="orientation.w"/>
      <state_interface name="angular_velocity.x"/>
      <state_interface name="angular_velocity.y"/>
      <state_interface name="angular_velocity.z"/>
      <state_interface name="linear_acceleration.x"/>
      <state_interface name="linear_acceleration.y"/>
      <state_interface name="linear_acceleration.z"/>
    </sensor>
    <sensor name="end_of_frame_sensor">
      <state_interface name="right_bar_touched" />
    </sensor>
  </ros2_control>

  <gazebo>
    <plugin filename="gz_ros2_control-system" name="gz_ros2_control::GazeboSimROS2ControlPlugin">
      <parameters>$(find gz_ros2_control_demos)/config/mason.yaml</parameters>
    </plugin>
    <plugin filename="gz-sim-imu-system" name="gz::sim::systems::Imu" />
    <plugin name='gz::sim::systems::Contact' filename='gz-sim-contact-system' />
    <!-- <plugin name="gz::sensors::DepthCamera" filename="gz-sensors-depth-camera">
      <frame_name>camera_frame_link</frame_name>
    </plugin> -->
  </gazebo>

</robot>