<?xml version="1.0"?>
<robot xmlns:xacro="http://www.ros.org/wiki/xacro" name="single_wheel_robot">

  <!-- Base Link -->
  <link name="base_link">
    <visual>
      <geometry>
        <box size="0.5 0.5 0.1"/>
      </geometry>
      <material name="blue">
        <color rgba="0.0 0.0 1.0 1.0"/>
      </material>
    </visual>
    <collision>
      <geometry>
        <box size="0.5 0.5 0.1"/>
      </geometry>
    </collision>
    <inertial>
      <mass value="1.0"/>
      <inertia ixx="0.1" ixy="0.0" ixz="0.0" iyy="0.1" iyz="0.0" izz="0.1"/>
    </inertial>
  </link>

  <!-- Wheel Link -->
  <link name="wheel">
    <visual>
      <geometry>
        <cylinder radius="0.1" length="0.05"/>
      </geometry>
      <material name="black">
        <color rgba="0.0 0.0 0.0 1.0"/>
      </material>
    </visual>
    <collision>
      <geometry>
        <cylinder radius="0.1" length="0.05"/>
      </geometry>
    </collision>
    <inertial>
      <mass value="0.5"/>
      <inertia ixx="0.01" ixy="0.0" ixz="0.0" iyy="0.01" iyz="0.0" izz="0.01"/>
    </inertial>
  </link>

  <!-- Joint -->
  <joint name="wheel_joint" type="continuous">
    <parent link="base_link"/>
    <child link="wheel"/>
    <origin xyz="0 0 -0.1" rpy="0 0 0"/>
    <axis xyz="0 1 0"/>
  </joint>

  <ros2_control name="single_wheel_robot" type="system">
    <hardware>
      <plugin>mason_hardware/MasonInterface</plugin>
      <param name="left_motor_name">MotorJointLeft</param>
      <param name="right_motor_name">MotorJointRight</param>
      <param name="horizontal_motor_name">MotorTop</param>
      <param name="device">/dev/ttyACM0</param>
      <param name="baud_rate">115200</param>
    </hardware>
    <joint name="wheel_joint">
      <command_interface name="velocity"/>
      <state_interface name="position"/>
      <state_interface name="velocity"/>
    </joint>
  </ros2_control>
</robot>
